Workbook
Name SERVER: #REF!
Name SERVER: #REF!
Name SERVER: #REF!
Name SERVER: #REF!
Name SERVER: #REF!
Name SERVER: #REF!
Name SERVER: #REF!
Name SERVER: #REF!
Name SERVER: #REF!
Name SERVER: #REF!
Name SERVER: #REF!
Name SERVER: #REF!
Name SERVER: #REF!
Name SERVER: #REF!
Name SERVER: #REF!
Name SERVER: '[1]2017 Forecast'!$E$19
Name spec: #REF!
Name spec: #REF!
Name spec: #REF!
Name spec: #REF!
Name spec: #REF!
Name spec: #REF!
Name spec: #REF!
Name spec: #REF!
Name spec: [2]Montreal!#REF!
Name spec: #REF!
Name spec: #REF!
Name spec: #REF!
Name spec: #REF!
Name spec: #REF!
Name spec: #REF!
Name spec: #REF!
Name spec: [2]Montreal!#REF!
Name TM1REBUILDOPTION: 1

Sheet RDG Weekly
D2: =CONCATENATE("Riviera Dining Group - Profit & Loss",) -> Riviera Dining Group - Profit & Loss | AK2: Weekly Budget | AU2: Month to Date
D3: =CONCATENATE(E3," ",F3) -> #REF! | E3: Week | F3: =+#REF! -> #REF! | X3: =+#REF! -> #REF!
B4: ACT. | C4: eUD. | D4: =CONCATENATE(E4," ",F4) -> #REF! | E4: Week | F4: =+F3+1 -> #REF! | X4: =+X3+1 -> #REF!
B5: ACT. | C5: BUD. | D5: =CONCATENATE(E5," ",F5) -> #REF! | E5: Week | F5: =+F4+1 -> #REF! | X5: =+X4+1 -> #REF!
B6: ACT. | C6: BUD. | D6: =CONCATENATE(E6," ",F6) -> #REF! | E6: Week | F6: =+F5+1 -> #REF! | X6: =+X5+1 -> #REF!
B7: ACT. | C7: BUD. | D7: =CONCATENATE(E7," ",F7) -> #REF! | E7: Week | F7: =+F6+1 -> #REF! | X7: =+X6+1 -> #REF!
B8: ACT. | C8: BUD.
B9: =VLOOKUP($D9,'[3]REF #'!$C:$E,2,FALSE) -> #REF! | C9: =VLOOKUP($D9,'[3]REF #'!$C:$E,3,FALSE) -> #REF! | D9: =+#REF! -> #REF! | F9: MTD | X9: YTD | AK9: =+D3 -> #REF! | AM9: =+D4 -> #REF! | AO9: =+D5 -> #REF! | AQ9: =+D6 -> #REF! | AU9: =+D3 -> #REF! | AY9: =+D4 -> #REF! | BC9: =+D5 -> #REF!
F11: MILA 3F | I11: MILA 2F | M11: AVA | Q11: CASA NEOS | X11: MILA | AB11: MILA MM | AE11: AVA | AG11: BAOLI | AK11: BUDGET | AM11: BUDGET | AO11: BUDGET | AQ11: BUDGET | AU11: 2023 | AW11: BUDGET | AY11: 2023 | BA11: BUDGET | BC11: 2023 | BE11: BUDGET
B13: Total Sales | D13: Net Sales | F13: =SUMIFS(#REF!,#REF!,$B$13) -> #REF! | G13: =IFERROR(F13/F13,0) -> 0 | I13: =SUMIFS(#REF!,#REF!,$B$13) -> #REF! | K13: =IFERROR(I13/I13,0) -> 0 | M13: =SUMIFS(#REF!,#REF!,$B$13) -> #REF! | O13: =IFERROR(M13/M13,0) -> 0 | Q13: =SUMIFS(#REF!,#REF!,$B$13) -> #REF! | S13: =IFERROR(Q13/Q13,0) -> 0 | X13: =SUMIFS(#REF!,#REF!,'RDG Weekly'!Q13) -> #REF! | Z13: =IFERROR(X13/X13,0) -> 0 | AB13: =SUMIFS(#REF!,#REF!,'RDG Weekly'!Q13) -> #REF! | AD13: =IFERROR(AB13/AB13,0) -> 0 | AE13: =SUMIFS(#REF!,#REF!,'RDG Weekly'!Q13) -> #REF! | AF13: =IFERROR(AE13/AE13,0) -> 0 | AG13: =SUMIFS(#REF!,#REF!,'RDG Weekly'!Q13) -> #REF! | AH13: =IFERROR(AG13/AG13,0) -> 0 | AK13: =VLOOKUP(D3,#REF!,2,FALSE) -> #REF! | AL13: =IFERROR(AK13/AK13,0) -> 0 | AM13: =VLOOKUP(D4,#REF!,2,FALSE) -> #REF! | AN13: =IFERROR(AM13/AM13,0) -> 0 | AO13: =VLOOKUP(D5,#REF!,2,FALSE) -> #REF! | AP13: =IFERROR(AO13/AO13,0) -> 0 | AQ13: =VLOOKUP(D6,#REF!,2,FALSE) -> #REF! | AR13: =IFERROR(AQ13/AQ13,0) -> 0 | AU13: =SUMIFS($F$13:$F$34,$D$13:$D$34,D13) -> #REF! | AV13: =IFERROR(AU13/AU13,0) -> 0 | AW13: =+AK13 -> #REF! | AX13: =IFERROR(AW13/AW13,0) -> 0 | AY13: =SUMIFS($I$13:$I$34,$D$13:$D$34,D13)+SUMIFS($AU$13:$AU$34,$D$13:$D$34,D13) -> #REF! | AZ13: =IFERROR(AY13/AY13,0) -> 0 | BA13: =SUMIFS($AM$13:$AM$34,$D$13:$D$34,D13)+SUMIFS($AW$13:$AW$34,$D$13:$D$34,D13) -> #REF! | BB13: =IFERROR(BA13/BA13,0) -> 0 | BC13: =SUMIFS($M$13:$M$34,$D$13:$D$34,D13)+SUMIFS($AY$13:$AY$34,$D$13:$D$34,D13) -> #REF! | BD13: =IFERROR(BC13/BC13,0) -> 0 | BE13: =SUMIFS($AO$13:$AO$34,$D$13:$D$34,D13)+SUMIFS($BA$13:$BA$34,$D$13:$D$34,D13) -> #REF! | BF13: =IFERROR(BE13/BE13,0) -> 0
B14: Total Food Cost | D14: Cost of Goods Sold | F14: =SUMIFS(#REF!,#REF!,'RDG Weekly'!$B$14)+SUMIFS(#REF!,#REF!,'RDG Weekly'!$B$15)+SUMIFS(#REF!,#REF!,'RDG Weekly'!$B$16) -> #REF! | G14: =IFERROR(F14/F13,0) -> 0 | I14: =SUMIFS(#REF!,#REF!,'RDG Weekly'!$B$14)+SUMIFS(#REF!,#REF!,'RDG Weekly'!$B$15)+SUMIFS(#REF!,#REF!,'RDG Weekly'!$B$16) -> #REF! | K14: =IFERROR(I14/I13,0) -> 0 | M14: =SUMIFS(#REF!,#REF!,'RDG Weekly'!$B$14)+SUMIFS(#REF!,#REF!,'RDG Weekly'!$B$15)+SUMIFS(#REF!,#REF!,'RDG Weekly'!$B$16) -> #REF! | O14: =IFERROR(M14/M13,0) -> 0 | Q14: =SUMIFS(#REF!,#REF!,'RDG Weekly'!$B$14)+SUMIFS(#REF!,#REF!,'RDG Weekly'!$B$15)+SUMIFS(#REF!,#REF!,'RDG Weekly'!$B$16) -> #REF! | S14: =IFERROR(Q14/Q13,0) -> 0 | X14: =SUMIFS(#REF!,#REF!,'RDG Weekly'!Q14)+SUMIFS(#REF!,#REF!,'RDG Weekly'!Q15)+SUMIFS(#REF!,#REF!,'RDG Weekly'!Q16) -> #REF! | Z14: =IFERROR(X14/X13,0) -> 0 | AB14: =SUMIFS(#REF!,#REF!,'RDG Weekly'!Q14)+SUMIFS(#REF!,#REF!,'RDG Weekly'!Q15)+SUMIFS(#REF!,#REF!,'RDG Weekly'!Q16) -> #REF! | AD14: =IFERROR(AB14/AB13,0) -> 0 | AE14: =SUMIFS(#REF!,#REF!,'RDG Weekly'!Q14)+SUMIFS(#REF!,#REF!,'RDG Weekly'!Q15)+SUMIFS(#REF!,#REF!,'RDG Weekly'!Q16) -> #REF! | AF14: =IFERROR(AE14/AE13,0) -> 0 | AG14: =SUMIFS(#REF!,#REF!,'RDG Weekly'!Q14)+SUMIFS(#REF!,#REF!,'RDG Weekly'!Q15)+SUMIFS(#REF!,#REF!,'RDG Weekly'!Q16) -> #REF! | AH14: =IFERROR(AG14/AG13,0) -> 0 | AK14: =+#REF! -> #REF! | AL14: =IFERROR(AK14/AK13,0) -> 0 | AM14: =+#REF! -> #REF! | AN14: =IFERROR(AM14/AM13,0) -> 0 | AO14: =+#REF! -> #REF! | AP14: =IFERROR(AO14/AO13,0) -> 0 | AQ14: =+AP14*AQ13 -> #REF! | AR14: =IFERROR(AQ14/AQ13,0) -> 0 | AU14: =SUMIFS($F$13:$F$34,$D$13:$D$34,D14) -> #REF! | AV14: =IFERROR(AU14/AU13,0) -> 0 | AW14: =+AK14 -> #REF! | AX14: =IFERROR(AW14/AW13,0) -> 0 | AY14: =SUMIFS($I$13:$I$34,$D$13:$D$34,D14)+SUMIFS($AU$13:$AU$34,$D$13:$D$34,D14) -> #REF! | AZ14: =IFERROR(AY14/AY13,0) -> 0 | BA14: =SUMIFS($AM$13:$AM$34,$D$13:$D$34,D14)+SUMIFS($AW$13:$AW$34,$D$13:$D$34,D14) -> #REF! | BB14: =IFERROR(BA14/BA13,0) -> 0 | BC14: =SUMIFS($M$13:$M$34,$D$13:$D$34,D14)+SUMIFS($AY$13:$AY$34,$D$13:$D$34,D14) -> #REF! | BD14: =IFERROR(BC14/BC13,0) -> 0 | BE14: =SUMIFS($AO$13:$AO$34,$D$13:$D$34,D14)+SUMIFS($BA$13:$BA$34,$D$13:$D$34,D14) -> #REF! | BF14: =IFERROR(BE14/BE13,0) -> 0
B15: 5080 - Purchase N/A Beverages
B16: Total LBW Cost | D16: Gross Profit | F16: =F13-F14 -> #REF! | G16: =IFERROR(F16/F13,0) -> 0 | I16: =I13-I14 -> #REF! | K16: =IFERROR(I16/I13,0) -> 0 | M16: =M13-M14 -> #REF! | O16: =IFERROR(M16/M13,0) -> 0 | Q16: =Q13-Q14 -> #REF! | S16: =IFERROR(Q16/Q13,0) -> 0 | X16: =X13-X14 -> #REF! | Z16: =IFERROR(X16/X13,0) -> 0 | AB16: =AB13-AB14 -> #REF! | AD16: =IFERROR(AB16/AB13,0) -> 0 | AE16: =AE13-AE14 -> #REF! | AF16: =IFERROR(AE16/AE13,0) -> 0 | AG16: =AG13-AG14 -> #REF! | AH16: =IFERROR(AG16/AG13,0) -> 0 | AK16: =AK13-AK14 -> #REF! | AL16: =IFERROR(AK16/AK13,0) -> 0 | AM16: =AM13-AM14 -> #REF! | AN16: =IFERROR(AM16/AM13,0) -> 0 | AO16: =AO13-AO14 -> #REF! | AP16: =IFERROR(AO16/AO13,0) -> 0 | AQ16: =AQ13-AQ14 -> #REF! | AR16: =IFERROR(AQ16/AQ13,0) -> 0 | AU16: =AU13-AU14 -> #REF! | AV16: =IFERROR(AU16/AU13,0) -> 0 | AW16: =AW13-AW14 -> #REF! | AX16: =IFERROR(AW16/AW13,0) -> 0 | AY16: =AY13-AY14 -> #REF! | AZ16: =IFERROR(AY16/AY13,0) -> 0 | BA16: =BA13-BA14 -> #REF! | BB16: =IFERROR(BA16/BA13,0) -> 0 | BC16: =BC13-BC14 -> #REF! | BD16: =IFERROR(BC16/BC13,0) -> 0 | BE16: =BE13-BE14 -> #REF! | BF16: =IFERROR(BE16/BE13,0) -> 0
B18: Total Payroll Expenses | C18: Total Salaries and Wages | D18: Cost of Labor | F18: =+SUMIFS(#REF!,#REF!,'RDG Weekly'!B18)+SUMIFS(#REF!,#REF!,'RDG Weekly'!C18)+SUMIFS(#REF!,#REF!,'RDG Weekly'!C22)+SUMIFS(#REF!,#REF!,'RDG Weekly'!C23) -> #REF! | G18: =IFERROR(F18/F13,0) -> 0 | I18: =+SUMIFS(#REF!,#REF!,'RDG Weekly'!B18)+SUMIFS(#REF!,#REF!,'RDG Weekly'!C18)+SUMIFS(#REF!,#REF!,'RDG Weekly'!C22)+SUMIFS(#REF!,#REF!,'RDG Weekly'!C23) -> #REF! | K18: =IFERROR(I18/I13,0) -> 0 | M18: =+SUMIFS(#REF!,#REF!,'RDG Weekly'!B18)+SUMIFS(#REF!,#REF!,'RDG Weekly'!C18)+SUMIFS(#REF!,#REF!,'RDG Weekly'!C22)+SUMIFS(#REF!,#REF!,'RDG Weekly'!C23) -> #REF! | O18: =IFERROR(M18/M13,0) -> 0 | Q18: =+SUMIFS(#REF!,#REF!,'RDG Weekly'!B18)+SUMIFS(#REF!,#REF!,'RDG Weekly'!C18)+SUMIFS(#REF!,#REF!,'RDG Weekly'!C22)+SUMIFS(#REF!,#REF!,'RDG Weekly'!C23) -> #REF! | S18: =IFERROR(Q18/Q13,0) -> 0 | X18: =+SUMIFS(#REF!,#REF!,'RDG Weekly'!Q18)+SUMIFS(#REF!,#REF!,'RDG Weekly'!S18)+SUMIFS(#REF!,#REF!,'RDG Weekly'!S22)+SUMIFS(#REF!,#REF!,'RDG Weekly'!S23) -> #REF! | Z18: =IFERROR(X18/X13,0) -> 0 | AB18: =+SUMIFS(#REF!,#REF!,'RDG Weekly'!Q18)+SUMIFS(#REF!,#REF!,'RDG Weekly'!S18)+SUMIFS(#REF!,#REF!,'RDG Weekly'!S22)+SUMIFS(#REF!,#REF!,'RDG Weekly'!S23) -> #REF! | AD18: =IFERROR(AB18/AB13,0) -> 0 | AE18: =+SUMIFS(#REF!,#REF!,'RDG Weekly'!Q18)+SUMIFS(#REF!,#REF!,'RDG Weekly'!S18)+SUMIFS(#REF!,#REF!,'RDG Weekly'!S22)+SUMIFS(#REF!,#REF!,'RDG Weekly'!S23) -> #REF! | AF18: =IFERROR(AE18/AE13,0) -> 0 | AG18: =+SUMIFS(#REF!,#REF!,'RDG Weekly'!Q18)+SUMIFS(#REF!,#REF!,'RDG Weekly'!S18)+SUMIFS(#REF!,#REF!,'RDG Weekly'!S22)+SUMIFS(#REF!,#REF!,'RDG Weekly'!S23) -> #REF! | AH18: =IFERROR(AG18/AG13,0) -> 0 | AK18: =+#REF! -> #REF! | AL18: =IFERROR(AK18/AK13,0) -> 0 | AM18: =+AK18 -> #REF! | AN18: =IFERROR(AM18/AM13,0) -> 0 | AO18: =+AM18 -> #REF! | AP18: =IFERROR(AO18/AO13,0) -> 0 | AQ18: =+AO18 -> #REF! | AR18: =IFERROR(AQ18/AQ13,0) -> 0 | AU18: =SUMIFS($F$13:$F$34,$D$13:$D$34,D18) -> #REF! | AV18: =IFERROR(AU18/AU13,0) -> 0 | AW18: =+AK18 -> #REF! | AX18: =IFERROR(AW18/AW13,0) -> 0 | AY18: =SUMIFS($I$13:$I$34,$D$13:$D$34,D18)+SUMIFS($AU$13:$AU$34,$D$13:$D$34,D18) -> #REF! | AZ18: =IFERROR(AY18/AY13,0) -> 0 | BA18: =SUMIFS($AM$13:$AM$34,$D$13:$D$34,D18)+SUMIFS($AW$13:$AW$34,$D$13:$D$34,D18) -> #REF! | BB18: =IFERROR(BA18/BA13,0) -> 0 | BC18: =SUMIFS($M$13:$M$34,$D$13:$D$34,D18)+SUMIFS($AY$13:$AY$34,$D$13:$D$34,D18) -> #REF! | BD18: =IFERROR(BC18/BC13,0) -> 0 | BE18: =SUMIFS($AO$13:$AO$34,$D$13:$D$34,D18)+SUMIFS($BA$13:$BA$34,$D$13:$D$34,D18) -> #REF! | BF18: =IFERROR(BE18/BE13,0) -> 0
D19: FOH - Hourly | F19: =+SUMIFS(#REF!,#REF!,'RDG Weekly'!B18)-F20 -> #REF! | G19: =+F19/$F$13 -> #REF! | I19: =+SUMIFS(#REF!,#REF!,'RDG Weekly'!B18)-I20 -> #REF! | K19: =+I19/$I$13 -> #REF! | M19: =+SUMIFS(#REF!,#REF!,'RDG Weekly'!B18)-M20 -> #REF! | O19: =+M19/$M$13 -> #REF! | Q19: =+SUMIFS(#REF!,#REF!,'RDG Weekly'!B18)-Q20 -> #REF! | S19: =+Q19/$M$13 -> #REF! | X19: =+SUMIFS(#REF!,#REF!,'RDG Weekly'!Q18)-X20 -> #REF! | Z19: =+X19/$F$13 -> #REF! | AB19: =+SUMIFS(#REF!,#REF!,'RDG Weekly'!Q18)-AB20 -> #REF! | AD19: =+AB19/$I$13 -> #REF! | AE19: =+SUMIFS(#REF!,#REF!,'RDG Weekly'!Q18)-AE20 -> #REF! | AF19: =+AE19/$M$13 -> #REF! | AG19: =+SUMIFS(#REF!,#REF!,'RDG Weekly'!Q18)-AG20 -> #REF! | AH19: =+AG19/$M$13 -> #REF! | AK19: =+#REF! -> #REF! | AL19: =+AK19/$AK$13 -> #REF! | AM19: =+AK19 -> #REF! | AN19: =+AM19/$AM$13 -> #REF! | AO19: =+AM19 -> #REF! | AP19: =+AO19/$AO$13 -> #REF! | AQ19: =+AO19 -> #REF! | AR19: =+AQ19/$AQ$13 -> #REF! | AU19: =SUMIFS($F$13:$F$34,$D$13:$D$34,D19) -> #REF! | AV19: =+AU19/$AU$13 -> #REF! | AW19: =+AK19 -> #REF! | AX19: =+AW19/$AW$13 -> #REF! | AY19: =SUMIFS($I$13:$I$34,$D$13:$D$34,D19)+SUMIFS($AU$13:$AU$34,$D$13:$D$34,D19) -> #REF! | AZ19: =+AY19/$AY$13 -> #REF! | BA19: =SUMIFS($AM$13:$AM$34,$D$13:$D$34,D19)+SUMIFS($AW$13:$AW$34,$D$13:$D$34,D19) -> #REF! | BB19: =+BA19/$BA$13 -> #REF! | BC19: =SUMIFS($M$13:$M$34,$D$13:$D$34,D19)+SUMIFS($AY$13:$AY$34,$D$13:$D$34,D19) -> #REF! | BD19: =+BC19/$BC$13 -> #REF! | BE19: =SUMIFS($AO$13:$AO$34,$D$13:$D$34,D19)+SUMIFS($BA$13:$BA$34,$D$13:$D$34,D19) -> #REF! | BF19: =+BE19/$BE$13 -> #REF!
D20: BOH - Hourly | G20: =+F20/$F$13 -> #REF! | I20: =+SUMIFS(#REF!,#REF!,'RDG Weekly'!B223)+SUMIFS(#REF!,#REF!,'RDG Weekly'!B224)+SUMIFS(#REF!,#REF!,'RDG Weekly'!B225)+SUMIFS(#REF!,#REF!,'RDG Weekly'!B226)+SUMIFS(#REF!,#REF!,'RDG Weekly'!B227)+SUMIFS(#REF!,#REF!,'RDG Weekly'!B228)+SUMIFS(#REF!,#REF!,'RDG Weekly'!B229)+SUMIFS(#REF!,#REF!,'RDG Weekly'!B230) -> #REF! | K20: =+I20/$I$13 -> #REF! | M20: =+SUMIFS(#REF!,#REF!,'RDG Weekly'!B223)+SUMIFS(#REF!,#REF!,'RDG Weekly'!B224)+SUMIFS(#REF!,#REF!,'RDG Weekly'!B225)+SUMIFS(#REF!,#REF!,'RDG Weekly'!B226)+SUMIFS(#REF!,#REF!,'RDG Weekly'!B227)+SUMIFS(#REF!,#REF!,'RDG Weekly'!B228)+SUMIFS(#REF!,#REF!,'RDG Weekly'!B229)+SUMIFS(#REF!,#REF!,'RDG Weekly'!B230) -> #REF! | O20: =+M20/$M$13 -> #REF! | Q20: =+SUMIFS(#REF!,#REF!,'RDG Weekly'!B223)+SUMIFS(#REF!,#REF!,'RDG Weekly'!B224)+SUMIFS(#REF!,#REF!,'RDG Weekly'!B225)+SUMIFS(#REF!,#REF!,'RDG Weekly'!B226)+SUMIFS(#REF!,#REF!,'RDG Weekly'!B227)+SUMIFS(#REF!,#REF!,'RDG Weekly'!B228)+SUMIFS(#REF!,#REF!,'RDG Weekly'!B229)+SUMIFS(#REF!,#REF!,'RDG Weekly'!B230) -> #REF! | S20: =+Q20/$M$13 -> #REF! | X20: =+SUMIFS(#REF!,#REF!,'RDG Weekly'!Q48)+SUMIFS(#REF!,#REF!,'RDG Weekly'!Q49)+SUMIFS(#REF!,#REF!,'RDG Weekly'!Q50)+SUMIFS(#REF!,#REF!,'RDG Weekly'!Q51)+SUMIFS(#REF!,#REF!,'RDG Weekly'!Q52)+SUMIFS(#REF!,#REF!,'RDG Weekly'!Q53)+SUMIFS(#REF!,#REF!,'RDG Weekly'!Q54)+SUMIFS(#REF!,#REF!,'RDG Weekly'!Q55) -> #REF! | Z20: =+X20/$F$13 -> #REF! | AB20: =+SUMIFS(#REF!,#REF!,'RDG Weekly'!Q48)+SUMIFS(#REF!,#REF!,'RDG Weekly'!Q49)+SUMIFS(#REF!,#REF!,'RDG Weekly'!Q50)+SUMIFS(#REF!,#REF!,'RDG Weekly'!Q51)+SUMIFS(#REF!,#REF!,'RDG Weekly'!Q52)+SUMIFS(#REF!,#REF!,'RDG Weekly'!Q53)+SUMIFS(#REF!,#REF!,'RDG Weekly'!Q54)+SUMIFS(#REF!,#REF!,'RDG Weekly'!Q55) -> #REF! | AD20: =+AB20/$I$13 -> #REF! | AE20: =+SUMIFS(#REF!,#REF!,'RDG Weekly'!Q48)+SUMIFS(#REF!,#REF!,'RDG Weekly'!Q49)+SUMIFS(#REF!,#REF!,'RDG Weekly'!Q50)+SUMIFS(#REF!,#REF!,'RDG Weekly'!Q51)+SUMIFS(#REF!,#REF!,'RDG Weekly'!Q52)+SUMIFS(#REF!,#REF!,'RDG Weekly'!Q53)+SUMIFS(#REF!,#REF!,'RDG Weekly'!Q54)+SUMIFS(#REF!,#REF!,'RDG Weekly'!Q55) -> #REF! | AF20: =+AE20/$M$13 -> #REF! | AG20: =+SUMIFS(#REF!,#REF!,'RDG Weekly'!Q48)+SUMIFS(#REF!,#REF!,'RDG Weekly'!Q49)+SUMIFS(#REF!,#REF!,'RDG Weekly'!Q50)+SUMIFS(#REF!,#REF!,'RDG Weekly'!Q51)+SUMIFS(#REF!,#REF!,'RDG Weekly'!Q52)+SUMIFS(#REF!,#REF!,'RDG Weekly'!Q53)+SUMIFS(#REF!,#REF!,'RDG Weekly'!Q54)+SUMIFS(#REF!,#REF!,'RDG Weekly'!Q55) -> #REF! | AH20: =+AG20/$M$13 -> #REF! | AK20: =+#REF! -> #REF! | AL20: =+AK20/$AK$13 -> #REF! | AM20: =+AK20 -> #REF! | AN20: =+AM20/$AM$13 -> #REF! | AO20: =+AM20 -> #REF! | AP20: =+AO20/$AO$13 -> #REF! | AQ20: =+AO20 -> #REF! | AR20: =+AQ20/$AQ$13 -> #REF! | AU20: =SUMIFS($F$13:$F$34,$D$13:$D$34,D20) -> 0 | AV20: =+AU20/$AU$13 -> #REF! | AW20: =+AK20 -> #REF! | AX20: =+AW20/$AW$13 -> #REF! | AY20: =SUMIFS($I$13:$I$34,$D$13:$D$34,D20)+SUMIFS($AU$13:$AU$34,$D$13:$D$34,D20) -> #REF! | AZ20: =+AY20/$AY$13 -> #REF! | BA20: =SUMIFS($AM$13:$AM$34,$D$13:$D$34,D20)+SUMIFS($AW$13:$AW$34,$D$13:$D$34,D20) -> #REF! | BB20: =+BA20/$BA$13 -> #REF! | BC20: =SUMIFS($M$13:$M$34,$D$13:$D$34,D20)+SUMIFS($AY$13:$AY$34,$D$13:$D$34,D20) -> #REF! | BD20: =+BC20/$BC$13 -> #REF! | BE20: =SUMIFS($AO$13:$AO$34,$D$13:$D$34,D20)+SUMIFS($BA$13:$BA$34,$D$13:$D$34,D20) -> #REF! | BF20: =+BE20/$BE$13 -> #REF!
D21: Management | F21: =+SUMIFS(#REF!,#REF!,'RDG Weekly'!C18) -> #REF! | G21: =+F21/$F$13 -> #REF! | I21: =+SUMIFS(#REF!,#REF!,'RDG Weekly'!C18) -> #REF! | K21: =+I21/$I$13 -> #REF! | M21: =+SUMIFS(#REF!,#REF!,'RDG Weekly'!C18) -> #REF! | O21: =+M21/$M$13 -> #REF! | Q21: =+SUMIFS(#REF!,#REF!,'RDG Weekly'!C18) -> #REF! | S21: =+Q21/$M$13 -> #REF! | X21: =+SUMIFS(#REF!,#REF!,'RDG Weekly'!S18) -> #REF! | Z21: =+X21/$F$13 -> #REF! | AB21: =+SUMIFS(#REF!,#REF!,'RDG Weekly'!S18) -> #REF! | AD21: =+AB21/$I$13 -> #REF! | AE21: =+SUMIFS(#REF!,#REF!,'RDG Weekly'!S18) -> #REF! | AF21: =+AE21/$M$13 -> #REF! | AG21: =+SUMIFS(#REF!,#REF!,'RDG Weekly'!S18) -> #REF! | AH21: =+AG21/$M$13 -> #REF! | AK21: =+#REF! -> #REF! | AL21: =+AK21/$AK$13 -> #REF! | AM21: =+AK21 -> #REF! | AN21: =+AM21/$AM$13 -> #REF! | AO21: =+AM21 -> #REF! | AP21: =+AO21/$AO$13 -> #REF! | AQ21: =+AO21 -> #REF! | AR21: =+AQ21/$AQ$13 -> #REF! | AU21: =SUMIFS($F$13:$F$34,$D$13:$D$34,D21) -> #REF! | AV21: =+AU21/$AU$13 -> #REF! | AW21: =+AK21 -> #REF! | AX21: =+AW21/$AW$13 -> #REF! | AY21: =SUMIFS($I$13:$I$34,$D$13:$D$34,D21)+SUMIFS($AU$13:$AU$34,$D$13:$D$34,D21) -> #REF! | AZ21: =+AY21/$AY$13 -> #REF! | BA21: =SUMIFS($AM$13:$AM$34,$D$13:$D$34,D21)+SUMIFS($AW$13:$AW$34,$D$13:$D$34,D21) -> #REF! | BB21: =+BA21/$BA$13 -> #REF! | BC21: =SUMIFS($M$13:$M$34,$D$13:$D$34,D21)+SUMIFS($AY$13:$AY$34,$D$13:$D$34,D21) -> #REF! | BD21: =+BC21/$BC$13 -> #REF! | BE21: =SUMIFS($AO$13:$AO$34,$D$13:$D$34,D21)+SUMIFS($BA$13:$BA$34,$D$13:$D$34,D21) -> #REF! | BF21: =+BE21/$BE$13 -> #REF!
B22: Total Occupancy | C22: Total Payroll Taxes | D22: Occupancy | F22: =+SUMIFS(#REF!,#REF!,'RDG Weekly'!B22) -> #REF! | G22: =IFERROR(F22/F13,0) -> 0 | I22: =+SUMIFS(#REF!,#REF!,'RDG Weekly'!B22) -> #REF! | K22: =IFERROR(I22/I13,0) -> 0 | M22: =+SUMIFS(#REF!,#REF!,'RDG Weekly'!B22) -> #REF! | O22: =IFERROR(M22/M13,0) -> 0 | Q22: =+SUMIFS(#REF!,#REF!,'RDG Weekly'!B22) -> #REF! | S22: =IFERROR(Q22/Q13,0) -> 0 | X22: =+SUMIFS(#REF!,#REF!,'RDG Weekly'!Q22) -> #REF! | Z22: =IFERROR(X22/X13,0) -> 0 | AB22: =+SUMIFS(#REF!,#REF!,'RDG Weekly'!Q22) -> #REF! | AD22: =IFERROR(AB22/AB13,0) -> 0 | AE22: =+SUMIFS(#REF!,#REF!,'RDG Weekly'!Q22) -> #REF! | AF22: =IFERROR(AE22/AE13,0) -> 0 | AG22: =+SUMIFS(#REF!,#REF!,'RDG Weekly'!Q22) -> #REF! | AH22: =IFERROR(AG22/AG13,0) -> 0 | AK22: =+#REF! -> #REF! | AL22: =IFERROR(AK22/AK13,0) -> 0 | AM22: =+AK22 -> #REF! | AN22: =IFERROR(AM22/AM13,0) -> 0 | AO22: =+AM22 -> #REF! | AP22: =IFERROR(AO22/AO13,0) -> 0 | AQ22: =+AO22 -> #REF! | AR22: =IFERROR(AQ22/AQ13,0) -> 0 | AU22: =SUMIFS($F$13:$F$34,$D$13:$D$34,D22) -> #REF! | AV22: =IFERROR(AU22/AU13,0) -> 0 | AW22: =+AK22 -> #REF! | AX22: =IFERROR(AW22/AW13,0) -> 0 | AY22: =SUMIFS($I$13:$I$34,$D$13:$D$34,D22)+SUMIFS($AU$13:$AU$34,$D$13:$D$34,D22) -> #REF! | AZ22: =IFERROR(AY22/AY13,0) -> 0 | BA22: =SUMIFS($AM$13:$AM$34,$D$13:$D$34,D22)+SUMIFS($AW$13:$AW$34,$D$13:$D$34,D22) -> #REF! | BB22: =IFERROR(BA22/BA13,0) -> 0 | BC22: =SUMIFS($M$13:$M$34,$D$13:$D$34,D22)+SUMIFS($AY$13:$AY$34,$D$13:$D$34,D22) -> #REF! | BD22: =IFERROR(BC22/BC13,0) -> 0 | BE22: =SUMIFS($AO$13:$AO$34,$D$13:$D$34,D22)+SUMIFS($BA$13:$BA$34,$D$13:$D$34,D22) -> #REF! | BF22: =IFERROR(BE22/BE13,0) -> 0
B23: Total Direct Operating Expenses | C23: 5970 - Group Health Insurance | D23: Operating Expenses | F23: =+SUMIFS(#REF!,#REF!,'RDG Weekly'!B23) -> #REF! | G23: =IFERROR(F23/F13,0) -> 0 | I23: =+SUMIFS(#REF!,#REF!,'RDG Weekly'!B23) -> #REF! | K23: =IFERROR(I23/I13,0) -> 0 | M23: =+SUMIFS(#REF!,#REF!,'RDG Weekly'!B23) -> #REF! | O23: =IFERROR(M23/M13,0) -> 0 | Q23: =+SUMIFS(#REF!,#REF!,'RDG Weekly'!B23) -> #REF! | S23: =IFERROR(Q23/Q13,0) -> 0 | X23: =+SUMIFS(#REF!,#REF!,'RDG Weekly'!Q23) -> #REF! | Z23: =IFERROR(X23/X13,0) -> 0 | AB23: =+SUMIFS(#REF!,#REF!,'RDG Weekly'!Q23) -> #REF! | AD23: =IFERROR(AB23/AB13,0) -> 0 | AE23: =+SUMIFS(#REF!,#REF!,'RDG Weekly'!Q23) -> #REF! | AF23: =IFERROR(AE23/AE13,0) -> 0 | AG23: =+SUMIFS(#REF!,#REF!,'RDG Weekly'!Q23) -> #REF! | AH23: =IFERROR(AG23/AG13,0) -> 0 | AK23: =+#REF! -> #REF! | AL23: =IFERROR(AK23/AK13,0) -> 0 | AM23: =+AK23 -> #REF! | AN23: =IFERROR(AM23/AM13,0) -> 0 | AO23: =+AM23 -> #REF! | AP23: =IFERROR(AO23/AO13,0) -> 0 | AQ23: =+AO23 -> #REF! | AR23: =IFERROR(AQ23/AQ13,0) -> 0 | AU23: =SUMIFS($F$13:$F$34,$D$13:$D$34,D23) -> #REF! | AV23: =IFERROR(AU23/AU13,0) -> 0 | AW23: =+AK23 -> #REF! | AX23: =IFERROR(AW23/AW13,0) -> 0 | AY23: =SUMIFS($I$13:$I$34,$D$13:$D$34,D23)+SUMIFS($AU$13:$AU$34,$D$13:$D$34,D23) -> #REF! | AZ23: =IFERROR(AY23/AY13,0) -> 0 | BA23: =SUMIFS($AM$13:$AM$34,$D$13:$D$34,D23)+SUMIFS($AW$13:$AW$34,$D$13:$D$34,D23) -> #REF! | BB23: =IFERROR(BA23/BA13,0) -> 0 | BC23: =SUMIFS($M$13:$M$34,$D$13:$D$34,D23)+SUMIFS($AY$13:$AY$34,$D$13:$D$34,D23) -> #REF! | BD23: =IFERROR(BC23/BC13,0) -> 0 | BE23: =SUMIFS($AO$13:$AO$34,$D$13:$D$34,D23)+SUMIFS($BA$13:$BA$34,$D$13:$D$34,D23) -> #REF! | BF23: =IFERROR(BE23/BE13,0) -> 0
B24: Total General and Administrative | D24: General & Administrative | F24: =+SUMIFS(#REF!,#REF!,'RDG Weekly'!B24) -> #REF! | G24: =IFERROR(F24/F13,0) -> 0 | I24: =+SUMIFS(#REF!,#REF!,'RDG Weekly'!B24) -> #REF! | K24: =IFERROR(I24/I13,0) -> 0 | M24: =+SUMIFS(#REF!,#REF!,'RDG Weekly'!B24) -> #REF! | O24: =IFERROR(M24/M13,0) -> 0 | Q24: =+SUMIFS(#REF!,#REF!,'RDG Weekly'!B24) -> #REF! | S24: =IFERROR(Q24/Q13,0) -> 0 | X24: =+SUMIFS(#REF!,#REF!,'RDG Weekly'!Q24) -> #REF! | Z24: =IFERROR(X24/X13,0) -> 0 | AB24: =+SUMIFS(#REF!,#REF!,'RDG Weekly'!Q24) -> #REF! | AD24: =IFERROR(AB24/AB13,0) -> 0 | AE24: =+SUMIFS(#REF!,#REF!,'RDG Weekly'!Q24) -> #REF! | AF24: =IFERROR(AE24/AE13,0) -> 0 | AG24: =+SUMIFS(#REF!,#REF!,'RDG Weekly'!Q24) -> #REF! | AH24: =IFERROR(AG24/AG13,0) -> 0 | AK24: =+#REF! -> #REF! | AL24: =IFERROR(AK24/AK13,0) -> 0 | AM24: =+AK24 -> #REF! | AN24: =IFERROR(AM24/AM13,0) -> 0 | AO24: =+AM24 -> #REF! | AP24: =IFERROR(AO24/AO13,0) -> 0 | AQ24: =+AO24 -> #REF! | AR24: =IFERROR(AQ24/AQ13,0) -> 0 | AU24: =SUMIFS($F$13:$F$34,$D$13:$D$34,D24) -> #REF! | AV24: =IFERROR(AU24/AU13,0) -> 0 | AW24: =+AK24 -> #REF! | AX24: =IFERROR(AW24/AW13,0) -> 0 | AY24: =SUMIFS($I$13:$I$34,$D$13:$D$34,D24)+SUMIFS($AU$13:$AU$34,$D$13:$D$34,D24) -> #REF! | AZ24: =IFERROR(AY24/AY13,0) -> 0 | BA24: =SUMIFS($AM$13:$AM$34,$D$13:$D$34,D24)+SUMIFS($AW$13:$AW$34,$D$13:$D$34,D24) -> #REF! | BB24: =IFERROR(BA24/BA13,0) -> 0 | BC24: =SUMIFS($M$13:$M$34,$D$13:$D$34,D24)+SUMIFS($AY$13:$AY$34,$D$13:$D$34,D24) -> #REF! | BD24: =IFERROR(BC24/BC13,0) -> 0 | BE24: =SUMIFS($AO$13:$AO$34,$D$13:$D$34,D24)+SUMIFS($BA$13:$BA$34,$D$13:$D$34,D24) -> #REF! | BF24: =IFERROR(BE24/BE13,0) -> 0
B25: Total Utilities | D25: Utilities | F25: =+SUMIFS(#REF!,#REF!,'RDG Weekly'!B25) -> #REF! | G25: =IFERROR(F25/F13,0) -> 0 | I25: =+SUMIFS(#REF!,#REF!,'RDG Weekly'!B25) -> #REF! | K25: =IFERROR(I25/I13,0) -> 0 | M25: =+SUMIFS(#REF!,#REF!,'RDG Weekly'!B25) -> #REF! | O25: =IFERROR(M25/M13,0) -> 0 | Q25: =+SUMIFS(#REF!,#REF!,'RDG Weekly'!B25) -> #REF! | S25: =IFERROR(Q25/Q13,0) -> 0 | X25: =+SUMIFS(#REF!,#REF!,'RDG Weekly'!Q25) -> #REF! | Z25: =IFERROR(X25/X13,0) -> 0 | AB25: =+SUMIFS(#REF!,#REF!,'RDG Weekly'!Q25) -> #REF! | AD25: =IFERROR(AB25/AB13,0) -> 0 | AE25: =+SUMIFS(#REF!,#REF!,'RDG Weekly'!Q25) -> #REF! | AF25: =IFERROR(AE25/AE13,0) -> 0 | AG25: =+SUMIFS(#REF!,#REF!,'RDG Weekly'!Q25) -> #REF! | AH25: =IFERROR(AG25/AG13,0) -> 0 | AK25: =+#REF! -> #REF! | AL25: =IFERROR(AK25/AK13,0) -> 0 | AM25: =+AK25 -> #REF! | AN25: =IFERROR(AM25/AM13,0) -> 0 | AO25: =+AM25 -> #REF! | AP25: =IFERROR(AO25/AO13,0) -> 0 | AQ25: =+AO25 -> #REF! | AR25: =IFERROR(AQ25/AQ13,0) -> 0 | AU25: =SUMIFS($F$13:$F$34,$D$13:$D$34,D25) -> #REF! | AV25: =IFERROR(AU25/AU13,0) -> 0 | AW25: =+AK25 -> #REF! | AX25: =IFERROR(AW25/AW13,0) -> 0 | AY25: =SUMIFS($I$13:$I$34,$D$13:$D$34,D25)+SUMIFS($AU$13:$AU$34,$D$13:$D$34,D25) -> #REF! | AZ25: =IFERROR(AY25/AY13,0) -> 0 | BA25: =SUMIFS($AM$13:$AM$34,$D$13:$D$34,D25)+SUMIFS($AW$13:$AW$34,$D$13:$D$34,D25) -> #REF! | BB25: =IFERROR(BA25/BA13,0) -> 0 | BC25: =SUMIFS($M$13:$M$34,$D$13:$D$34,D25)+SUMIFS($AY$13:$AY$34,$D$13:$D$34,D25) -> #REF! | BD25: =IFERROR(BC25/BC13,0) -> 0 | BE25: =SUMIFS($AO$13:$AO$34,$D$13:$D$34,D25)+SUMIFS($BA$13:$BA$34,$D$13:$D$34,D25) -> #REF! | BF25: =IFERROR(BE25/BE13,0) -> 0
B26: Total Other (Income) Expenses | D26: Other Income | F26: =+SUMIFS(#REF!,#REF!,'RDG Weekly'!B26) -> #REF! | G26: =IFERROR(F26/F13,0) -> 0 | I26: =+SUMIFS(#REF!,#REF!,'RDG Weekly'!B26) -> #REF! | K26: =IFERROR(I26/I13,0) -> 0 | M26: =+SUMIFS(#REF!,#REF!,'RDG Weekly'!B26) -> #REF! | O26: =IFERROR(M26/M13,0) -> 0 | Q26: =+SUMIFS(#REF!,#REF!,'RDG Weekly'!B26) -> #REF! | S26: =IFERROR(Q26/Q13,0) -> 0 | X26: =+SUMIFS(#REF!,#REF!,'RDG Weekly'!Q26) -> #REF! | Z26: =IFERROR(X26/X13,0) -> 0 | AB26: =+SUMIFS(#REF!,#REF!,'RDG Weekly'!Q26) -> #REF! | AD26: =IFERROR(AB26/AB13,0) -> 0 | AE26: =+SUMIFS(#REF!,#REF!,'RDG Weekly'!Q26) -> #REF! | AF26: =IFERROR(AE26/AE13,0) -> 0 | AG26: =+SUMIFS(#REF!,#REF!,'RDG Weekly'!Q26) -> #REF! | AH26: =IFERROR(AG26/AG13,0) -> 0 | AK26: =+#REF! -> #REF! | AL26: =IFERROR(AK26/AK13,0) -> 0 | AM26: =+AK26 -> #REF! | AN26: =IFERROR(AM26/AM13,0) -> 0 | AO26: =+AM26 -> #REF! | AP26: =IFERROR(AO26/AO13,0) -> 0 | AQ26: =+AO26 -> #REF! | AR26: =IFERROR(AQ26/AQ13,0) -> 0 | AU26: =SUMIFS($F$13:$F$34,$D$13:$D$34,D26) -> #REF! | AV26: =IFERROR(AU26/AU13,0) -> 0 | AW26: =+AK26 -> #REF! | AX26: =IFERROR(AW26/AW13,0) -> 0 | AY26: =SUMIFS($I$13:$I$34,$D$13:$D$34,D26)+SUMIFS($AU$13:$AU$34,$D$13:$D$34,D26) -> #REF! | AZ26: =IFERROR(AY26/AY13,0) -> 0 | BA26: =SUMIFS($AM$13:$AM$34,$D$13:$D$34,D26)+SUMIFS($AW$13:$AW$34,$D$13:$D$34,D26) -> #REF! | BB26: =IFERROR(BA26/BA13,0) -> 0 | BC26: =SUMIFS($M$13:$M$34,$D$13:$D$34,D26)+SUMIFS($AY$13:$AY$34,$D$13:$D$34,D26) -> #REF! | BD26: =IFERROR(BC26/BC13,0) -> 0 | BE26: =SUMIFS($AO$13:$AO$34,$D$13:$D$34,D26)+SUMIFS($BA$13:$BA$34,$D$13:$D$34,D26) -> #REF! | BF26: =IFERROR(BE26/BE13,0) -> 0
D28: Total Operating Expenses | F28: =SUM(F22:F26,F18) -> #REF! | G28: =IFERROR(F28/F13,0) -> 0 | I28: =SUM(I22:I26,I18) -> #REF! | K28: =IFERROR(I28/I13,0) -> 0 | M28: =SUM(M22:M26,M18) -> #REF! | O28: =IFERROR(M28/M13,0) -> 0 | Q28: =SUM(Q22:Q26,Q18) -> #REF! | S28: =IFERROR(Q28/Q13,0) -> 0 | X28: =SUM(X22:X26,X18) -> #REF! | Z28: =IFERROR(X28/X13,0) -> 0 | AB28: =SUM(AB22:AB26,AB18) -> #REF! | AD28: =IFERROR(AB28/AB13,0) -> 0 | AE28: =SUM(AE22:AE26,AE18) -> #REF! | AF28: =IFERROR(AE28/AE13,0) -> 0 | AG28: =SUM(AG22:AG26,AG18) -> #REF! | AH28: =IFERROR(AG28/AG13,0) -> 0 | AK28: =SUM(AK22:AK26,AK18) -> #REF! | AL28: =IFERROR(AK28/AK13,0) -> 0 | AM28: =SUM(AM22:AM26,AM18) -> #REF! | AN28: =IFERROR(AM28/AM13,0) -> 0 | AO28: =SUM(AO22:AO26,AO18) -> #REF! | AP28: =IFERROR(AO28/AO13,0) -> 0 | AQ28: =SUM(AQ22:AQ26,AQ18) -> #REF! | AR28: =IFERROR(AQ28/AQ13,0) -> 0 | AU28: =SUM(AU22:AU26,AU18) -> #REF! | AV28: =IFERROR(AU28/AU13,0) -> 0 | AW28: =SUM(AW22:AW26,AW18) -> #REF! | AX28: =IFERROR(AW28/AW13,0) -> 0 | AY28: =SUM(AY22:AY26,AY18) -> #REF! | AZ28: =IFERROR(AY28/AY13,0) -> 0 | BA28: =SUM(BA22:BA26,BA18) -> #REF! | BB28: =IFERROR(BA28/BA13,0) -> 0 | BC28: =SUM(BC22:BC26,BC18) -> #REF! | BD28: =IFERROR(BC28/BC13,0) -> 0 | BE28: =SUM(BE22:BE26,BE18) -> #REF! | BF28: =IFERROR(BE28/BE13,0) -> 0
D30: Net Operating Income | F30: =F16-F28 -> #REF! | G30: =IFERROR(F30/F13,0) -> 0 | I30: =I16-I28 -> #REF! | K30: =IFERROR(I30/I13,0) -> 0 | M30: =M16-M28 -> #REF! | O30: =IFERROR(M30/M13,0) -> 0 | Q30: =Q16-Q28 -> #REF! | S30: =IFERROR(Q30/Q13,0) -> 0 | X30: =X16-X28 -> #REF! | Z30: =IFERROR(X30/X13,0) -> 0 | AB30: =AB16-AB28 -> #REF! | AD30: =IFERROR(AB30/AB13,0) -> 0 | AE30: =AE16-AE28 -> #REF! | AF30: =IFERROR(AE30/AE13,0) -> 0 | AG30: =AG16-AG28 -> #REF! | AH30: =IFERROR(AG30/AG13,0) -> 0 | AK30: =AK16-AK28 -> #REF! | AL30: =IFERROR(AK30/AK13,0) -> 0 | AM30: =AM16-AM28 -> #REF! | AN30: =IFERROR(AM30/AM13,0) -> 0 | AO30: =AO16-AO28 -> #REF! | AP30: =IFERROR(AO30/AO13,0) -> 0 | AQ30: =AQ16-AQ28 -> #REF! | AR30: =IFERROR(AQ30/AQ13,0) -> 0 | AU30: =AU16-AU28 -> #REF! | AV30: =IFERROR(AU30/AU13,0) -> 0 | AW30: =AW16-AW28 -> #REF! | AX30: =IFERROR(AW30/AW13,0) -> 0 | AY30: =AY16-AY28 -> #REF! | AZ30: =IFERROR(AY30/AY13,0) -> 0 | BA30: =BA16-BA28 -> #REF! | BB30: =IFERROR(BA30/BA13,0) -> 0 | BC30: =BC16-BC28 -> #REF! | BD30: =IFERROR(BC30/BC13,0) -> 0 | BE30: =BE16-BE28 -> #REF! | BF30: =IFERROR(BE30/BE13,0) -> 0
B32: Total Corporate Overhead | D32: Other G&A | F32: =+SUMIFS(#REF!,#REF!,'RDG Weekly'!B32)-SUMIFS(#REF!,#REF!,'RDG Weekly'!B33) -> #REF! | G32: =IFERROR(F32/F13,0) -> 0 | I32: =+SUMIFS(#REF!,#REF!,'RDG Weekly'!B32) -> #REF! | K32: =IFERROR(I32/I13,0) -> 0 | M32: =+SUMIFS(#REF!,#REF!,'RDG Weekly'!B32) -> #REF! | O32: =IFERROR(M32/M13,0) -> 0 | Q32: =+SUMIFS(#REF!,#REF!,'RDG Weekly'!B32) -> #REF! | S32: =IFERROR(Q32/Q13,0) -> 0 | X32: =+SUMIFS(#REF!,#REF!,'RDG Weekly'!Q32)-SUMIFS(#REF!,#REF!,'RDG Weekly'!Q33) -> #REF! | Z32: =IFERROR(X32/X13,0) -> 0 | AB32: =+SUMIFS(#REF!,#REF!,'RDG Weekly'!Q32) -> #REF! | AD32: =IFERROR(AB32/AB13,0) -> 0 | AE32: =+SUMIFS(#REF!,#REF!,'RDG Weekly'!Q32) -> #REF! | AF32: =IFERROR(AE32/AE13,0) -> 0 | AG32: =+SUMIFS(#REF!,#REF!,'RDG Weekly'!Q32) -> #REF! | AH32: =IFERROR(AG32/AG13,0) -> 0 | AK32: =+#REF! -> #REF! | AL32: =IFERROR(AK32/AK13,0) -> 0 | AM32: =+AK32 -> #REF! | AN32: =IFERROR(AM32/AM13,0) -> 0 | AO32: =+AM32 -> #REF! | AP32: =IFERROR(AO32/AO13,0) -> 0 | AQ32: =+AO32 -> #REF! | AR32: =IFERROR(AQ32/AQ13,0) -> 0 | AU32: =SUMIFS($F$13:$F$34,$D$13:$D$34,D32) -> #REF! | AV32: =IFERROR(AU32/AU13,0) -> 0 | AW32: =+AK32 -> #REF! | AX32: =IFERROR(AW32/AW13,0) -> 0 | AY32: =SUMIFS($I$13:$I$34,$D$13:$D$34,D32)+SUMIFS($AU$13:$AU$34,$D$13:$D$34,D32) -> #REF! | AZ32: =IFERROR(AY32/AY13,0) -> 0 | BA32: =SUMIFS($AM$13:$AM$34,$D$13:$D$34,D32)+SUMIFS($AW$13:$AW$34,$D$13:$D$34,D32) -> #REF! | BB32: =IFERROR(BA32/BA13,0) -> 0 | BC32: =SUMIFS($M$13:$M$34,$D$13:$D$34,D32)+SUMIFS($AY$13:$AY$34,$D$13:$D$34,D32) -> #REF! | BD32: =IFERROR(BC32/BC13,0) -> 0 | BE32: =+AO32+BA32 -> #REF! | BF32: =IFERROR(BE32/BE13,0) -> 0
B33: 9205 - Depreciation Expense
B34: Total New Location | D34: EBITDA | F34: =F30-F32 -> #REF! | G34: =IFERROR(F34/F13,0) -> 0 | I34: =I30-I32 -> #REF! | K34: =IFERROR(I34/I13,0) -> 0 | M34: =M30-M32 -> #REF! | O34: =IFERROR(M34/M13,0) -> 0 | Q34: =Q30-Q32 -> #REF! | S34: =IFERROR(Q34/Q13,0) -> 0 | X34: =X30-X32 -> #REF! | Z34: =IFERROR(X34/X13,0) -> 0 | AB34: =AB30-AB32 -> #REF! | AD34: =IFERROR(AB34/AB13,0) -> 0 | AE34: =AE30-AE32 -> #REF! | AF34: =IFERROR(AE34/AE13,0) -> 0 | AG34: =AG30-AG32 -> #REF! | AH34: =IFERROR(AG34/AG13,0) -> 0 | AK34: =AK30-AK32 -> #REF! | AL34: =IFERROR(AK34/AK13,0) -> 0 | AM34: =AM30-AM32 -> #REF! | AN34: =IFERROR(AM34/AM13,0) -> 0 | AO34: =AO30-AO32 -> #REF! | AP34: =IFERROR(AO34/AO13,0) -> 0 | AQ34: =AQ30-AQ32 -> #REF! | AR34: =IFERROR(AQ34/AQ13,0) -> 0 | AU34: =AU30-AU32 -> #REF! | AV34: =IFERROR(AU34/AU13,0) -> 0 | AW34: =AW30-AW32 -> #REF! | AX34: =IFERROR(AW34/AW13,0) -> 0 | AY34: =AY30-AY32 -> #REF! | AZ34: =IFERROR(AY34/AY13,0) -> 0 | BA34: =BA30-BA32 -> #REF! | BB34: =IFERROR(BA34/BA13,0) -> 0 | BC34: =BC30-BC32 -> #REF! | BD34: =IFERROR(BC34/BC13,0) -> 0 | BE34: =BE30-BE32 -> #REF! | BF34: =IFERROR(BE34/BE13,0) -> 0
B35: 9010 - Interest Expense
D36: Key Performing Indicators | F36: =+F11 -> MILA 3F | I36: =+I11 -> MILA 2F | M36: =+M11 -> AVA | Q36: =+Q11 -> CASA NEOS | X36: =+X11 -> MILA | AB36: =+AB11 -> MILA MM | AE36: =+AE11 -> AVA | AG36: =+AG11 -> BAOLI
D38: Food Cost % | F38: =+SUMIFS(#REF!,#REF!,'RDG Weekly'!$B$213)/+SUMIFS(#REF!,#REF!,'RDG Weekly'!$B$212) -> #REF! | I38: =+SUMIFS(#REF!,#REF!,#REF!)/+SUMIFS(#REF!,#REF!,#REF!) -> #REF! | M38: =+SUMIFS(#REF!,#REF!,#REF!)/+SUMIFS(#REF!,#REF!,#REF!) -> #REF! | Q38: =+SUMIFS(#REF!,#REF!,#REF!)/+SUMIFS(#REF!,#REF!,#REF!) -> #REF! | X38: =+SUMIFS(#REF!,#REF!,'RDG Weekly'!$B$213)/+SUMIFS(#REF!,#REF!,'RDG Weekly'!$B$212) -> #REF! | AB38: =+SUMIFS(#REF!,#REF!,#REF!)/+SUMIFS(#REF!,#REF!,#REF!) -> #REF! | AE38: =+SUMIFS(#REF!,#REF!,#REF!)/+SUMIFS(#REF!,#REF!,#REF!) -> #REF! | AG38: =+SUMIFS(#REF!,#REF!,#REF!)/+SUMIFS(#REF!,#REF!,#REF!) -> #REF!
D39: Liqour % | F39: =+(SUMIFS(#REF!,#REF!,'RDG Weekly'!$C$215)+SUMIFS(#REF!,#REF!,'RDG Weekly'!$C$218))/+SUMIFS(#REF!,#REF!,'RDG Weekly'!$C$214) -> #REF! | I39: =+(SUMIFS(#REF!,#REF!,#REF!)+SUMIFS(#REF!,#REF!,#REF!))/+SUMIFS(#REF!,#REF!,#REF!) -> #REF! | M39: =+(SUMIFS(#REF!,#REF!,#REF!)+SUMIFS(#REF!,#REF!,#REF!))/+SUMIFS(#REF!,#REF!,#REF!) -> #REF! | Q39: =+(SUMIFS(#REF!,#REF!,#REF!)+SUMIFS(#REF!,#REF!,#REF!))/+SUMIFS(#REF!,#REF!,#REF!) -> #REF! | X39: =+(SUMIFS(#REF!,#REF!,'RDG Weekly'!$C$215)+SUMIFS(#REF!,#REF!,'RDG Weekly'!$C$218))/+SUMIFS(#REF!,#REF!,'RDG Weekly'!$C$214) -> #REF! | AB39: =+(SUMIFS(#REF!,#REF!,#REF!)+SUMIFS(#REF!,#REF!,#REF!))/+SUMIFS(#REF!,#REF!,#REF!) -> #REF! | AE39: =+(SUMIFS(#REF!,#REF!,#REF!)+SUMIFS(#REF!,#REF!,#REF!))/+SUMIFS(#REF!,#REF!,#REF!) -> #REF! | AG39: =+(SUMIFS(#REF!,#REF!,#REF!)+SUMIFS(#REF!,#REF!,#REF!))/+SUMIFS(#REF!,#REF!,#REF!) -> #REF!
D40: Wine % | F40: =+(SUMIFS(#REF!,#REF!,'RDG Weekly'!$B$219)++SUMIFS(#REF!,#REF!,'RDG Weekly'!$B$220)+SUMIFS(#REF!,#REF!,'RDG Weekly'!$B$221))/(+SUMIFS(#REF!,#REF!,'RDG Weekly'!$B$214)+SUMIFS(#REF!,#REF!,'RDG Weekly'!$B$215)+SUMIFS(#REF!,#REF!,'RDG Weekly'!$B$218)) -> #REF! | I40: =+(SUMIFS(#REF!,#REF!,#REF!)++SUMIFS(#REF!,#REF!,#REF!)+SUMIFS(#REF!,#REF!,#REF!))/(+SUMIFS(#REF!,#REF!,#REF!)+SUMIFS(#REF!,#REF!,#REF!)+SUMIFS(#REF!,#REF!,#REF!)) -> #REF! | M40: =+(SUMIFS(#REF!,#REF!,#REF!)++SUMIFS(#REF!,#REF!,#REF!)+SUMIFS(#REF!,#REF!,#REF!))/(+SUMIFS(#REF!,#REF!,#REF!)+SUMIFS(#REF!,#REF!,#REF!)+SUMIFS(#REF!,#REF!,#REF!)) -> #REF! | Q40: =+(SUMIFS(#REF!,#REF!,#REF!)++SUMIFS(#REF!,#REF!,#REF!)+SUMIFS(#REF!,#REF!,#REF!))/(+SUMIFS(#REF!,#REF!,#REF!)+SUMIFS(#REF!,#REF!,#REF!)+SUMIFS(#REF!,#REF!,#REF!)) -> #REF! | X40: =+(SUMIFS(#REF!,#REF!,'RDG Weekly'!$B$219)++SUMIFS(#REF!,#REF!,'RDG Weekly'!$B$220)+SUMIFS(#REF!,#REF!,'RDG Weekly'!$B$221))/(+SUMIFS(#REF!,#REF!,'RDG Weekly'!$B$214)+SUMIFS(#REF!,#REF!,'RDG Weekly'!$B$215)+SUMIFS(#REF!,#REF!,'RDG Weekly'!$B$218)) -> #REF! | AB40: =+(SUMIFS(#REF!,#REF!,#REF!)++SUMIFS(#REF!,#REF!,#REF!)+SUMIFS(#REF!,#REF!,#REF!))/(+SUMIFS(#REF!,#REF!,#REF!)+SUMIFS(#REF!,#REF!,#REF!)+SUMIFS(#REF!,#REF!,#REF!)) -> #REF! | AE40: =+(SUMIFS(#REF!,#REF!,#REF!)++SUMIFS(#REF!,#REF!,#REF!)+SUMIFS(#REF!,#REF!,#REF!))/(+SUMIFS(#REF!,#REF!,#REF!)+SUMIFS(#REF!,#REF!,#REF!)+SUMIFS(#REF!,#REF!,#REF!)) -> #REF! | AG40: =+(SUMIFS(#REF!,#REF!,#REF!)++SUMIFS(#REF!,#REF!,#REF!)+SUMIFS(#REF!,#REF!,#REF!))/(+SUMIFS(#REF!,#REF!,#REF!)+SUMIFS(#REF!,#REF!,#REF!)+SUMIFS(#REF!,#REF!,#REF!)) -> #REF!
D42: BOH Labour Cost % | F42: =F20/+SUMIFS(#REF!,#REF!,#REF!) -> #REF! | I42: =I20/+SUMIFS(#REF!,#REF!,B212) -> #REF! | M42: =M20/+SUMIFS(#REF!,#REF!,B212) -> #REF! | Q42: =Q20/+SUMIFS(#REF!,#REF!,B212) -> #REF! | X42: =X20/+SUMIFS(#REF!,#REF!,#REF!) -> #REF! | AB42: =AB20/+SUMIFS(#REF!,#REF!,Q37) -> #REF! | AE42: =AE20/+SUMIFS(#REF!,#REF!,Q37) -> #REF! | AG42: =AG20/+SUMIFS(#REF!,#REF!,Q37) -> #REF!
D44: Commentary
D46: Cost of Goods Sold | F46: Food cost upside in wk 5 with the buyout, liqour cost was steady with minimal variance of 6 btls which were rail product. Champ consumption during Brunch is till relativly high
D47: Cost of Labour | F47: BOH Casa Neo's chefs impacting MILA budget, along with RDG re-billing (Marketing/IT)
D48: Occupancy | F48: Turnover rent is higher due to higher sales vs budget
D49: Operating Expenses | F49: Tight spending for whole month of July, 38k upside within restaurant supplies (new napkins) that was realized within P5 accounts.
D50: General & Administrative | F50: Overage driven by storage fee 5k (no budget) & General liability insurance. (15k)
D51: Utilities
...

Sheet Reconciliation
B2: Week # | C2: Week 34
B3: Period | C3: {=_xlfn._xlws.FILTER(Table3[Period],Table3[Week '#]=Reconciliation!$C$2,"")} -> P8
B6: Week # | C6: Consolidated $ | D6: Actual - 2026 | E6: Variance
B7: {=_xlfn.UNIQUE(_xlfn._xlws.FILTER(CHOOSE({1,2},Table6[Week '#],SUMPRODUCT((Table6[Week '#]=Reconciliation!$C$2)*(Table6[Net sales]))),Table6[Week '#]=Reconciliation!$C$2,""))} -> Week 34 | C7: 2000757.3 | D7: =SUMIF('Actual - 2026'!$A$5:$A$56,$C$2,'Actual - 2026'!$K$5:$K$56)+SUMIF('Actual - 2026'!$A$5:$A$56,$C$2,'Actual - 2026'!$W$5:$W$56)+SUMIF('Actual - 2026'!$A$5:$A$56,$C$2,'Actual - 2026'!$AI$5:$AI$56)+SUMIF('Actual - 2026'!$A$5:$A$56,$C$2,'Actual - 2026'!$AR$5:$AR$56)+SUMIF('Actual - 2026'!$A$5:$A$56,$C$2,'Actual - 2026'!$BA$5:$BA$56)+SUMIF('Actual - 2026'!$A$5:$A$56,$C$2,'Actual - 2026'!$BM$5:$BM$56)+SUMIF('Actual - 2026'!$A$5:$A$56,$C$2,'Actual - 2026'!$BV$5:$BV$56) -> 1995361.8 | E7: =C7-D7 -> 5395.52
B8: Non-Grat Svc Charges | E8: {=SUMPRODUCT((Table4[Week '#]=Reconciliation!$C$2)*(Table4[Non-Grat Service $]))} -> 5552.87
B9: Total | E9: =E7-E8 -> -157.35
B13: Week # | C13: Day of Week | D13: Consolidated $
B14: {=_xlfn._xlws.FILTER(CHOOSE({1,2,3},Table6[Week '#],Table6[Day of Week],Table6[Net sales]),Table6[Week '#]=Reconciliation!$C$2,"")} -> Week 34 | C14: Monday | D14: 99798.77
B15: Week 34 | C15: Tuesday | D15: 170377.19
B16: Week 34 | C16: Wednesday | D16: 179832.09
B17: Week 34 | C17: Thursday | D17: 295283.89
B18: Week 34 | C18: Friday | D18: 440631.69
B19: Week 34 | C19: Saturday | D19: 511041.9
B20: Week 34 | C20: Sunday | D20: 303791.78
B21: Total | D21: =SUM(D14:D20) -> 2000757.3

Sheet Reference Tab
B3: DATE TABLE | H3: TOTAL SALES | P3: NON-GRATUITY SERVICE CHARGE
B5: Period | C5: Week # | D5: Start Date | E5: End Date | F5: Period 1 | H5: yyyyMMdd | I5: Net sales | J5: Total orders | K5: Total guests | L5: Date | M5: Day of Week | N5: Week # | P5: Period | Q5: Week # | R5: Start Date | S5: End Date | T5: Non-Grat Service $
B6: P1 | C6: Week 1 | D6: 46020 | E6: =Table3[[#This Row],[Start Date]]+6 -> 46026 | F6: Period 1 | H6: 20251229 | I6: 395375.12 | J6: 1227 | K6: 2791 | L6: =DATE(LEFT(H6,4),MID(H6,5,2),RIGHT(H6,2)) -> 46020 | M6: =TEXT(L6,"DDDD") -> Monday | N6: {=_xlfn._xlws.FILTER(Table3[Week '#],(Table3[Start Date]<=Table6[[#This Row],[Date]])*(Table3[End Date]>=Table6[[#This Row],[Date]]),"")} -> Week 1 | P6: P1 | Q6: Week 1 | R6: 46020 | S6: 46026 | T6: 4667.91
B7: P1 | C7: Week 2 | D7: =+E6+1 -> 46027 | E7: =Table3[[#This Row],[Start Date]]+6 -> 46033 | F7: Period 1 | H7: 20251230 | I7: 677868.52 | J7: 2060 | K7: 5012 | L7: =DATE(LEFT(H7,4),MID(H7,5,2),RIGHT(H7,2)) -> 46021 | M7: =TEXT(L7,"DDDD") -> Tuesday | N7: {=_xlfn._xlws.FILTER(Table3[Week '#],(Table3[Start Date]<=Table6[[#This Row],[Date]])*(Table3[End Date]>=Table6[[#This Row],[Date]]),"")} -> Week 1 | P7: P1 | Q7: Week 2 | R7: 46027 | S7: 46033 | T7: 27138.13
B8: P1 | C8: Week 3 | D8: =+E7+1 -> 46034 | E8: =Table3[[#This Row],[Start Date]]+6 -> 46040 | F8: Period 1 | H8: 20251231 | I8: 1515268 | J8: 1850 | K8: 4252 | L8: =DATE(LEFT(H8,4),MID(H8,5,2),RIGHT(H8,2)) -> 46022 | M8: =TEXT(L8,"DDDD") -> Wednesday | N8: {=_xlfn._xlws.FILTER(Table3[Week '#],(Table3[Start Date]<=Table6[[#This Row],[Date]])*(Table3[End Date]>=Table6[[#This Row],[Date]]),"")} -> Week 1 | P8: P1 | Q8: Week 3 | R8: 46034 | S8: 46040 | T8: 25872
B9: P1 | C9: Week 4 | D9: =+E8+1 -> 46041 | E9: =Table3[[#This Row],[Start Date]]+6 -> 46047 | F9: Period 2 | H9: 20260101 | I9: 398848.39 | J9: 1285 | K9: 3192 | L9: =DATE(LEFT(H9,4),MID(H9,5,2),RIGHT(H9,2)) -> 46023 | M9: =TEXT(L9,"DDDD") -> Thursday | N9: {=_xlfn._xlws.FILTER(Table3[Week '#],(Table3[Start Date]<=Table6[[#This Row],[Date]])*(Table3[End Date]>=Table6[[#This Row],[Date]]),"")} -> Week 1 | P9: P1 | Q9: Week 4 | R9: 46041 | S9: 46047 | T9: 19485.47
B10: P2 | C10: Week 5 | D10: =+E9+1 -> 46048 | E10: =Table3[[#This Row],[Start Date]]+6 -> 46054 | F10: Period 2 | H10: 20260102 | I10: 514278.04 | J10: 1768 | K10: 4087 | L10: =DATE(LEFT(H10,4),MID(H10,5,2),RIGHT(H10,2)) -> 46024 | M10: =TEXT(L10,"DDDD") -> Friday | N10: {=_xlfn._xlws.FILTER(Table3[Week '#],(Table3[Start Date]<=Table6[[#This Row],[Date]])*(Table3[End Date]>=Table6[[#This Row],[Date]]),"")} -> Week 1 | P10: P2 | Q10: Week 5 | R10: 46048 | S10: 46054 | T10: 25498.07
B11: P2 | C11: Week 6 | D11: =+E10+1 -> 46055 | E11: =Table3[[#This Row],[Start Date]]+6 -> 46061 | F11: Period 2 | H11: 20260103 | I11: 756008.97 | J11: 2673 | K11: 7579 | L11: =DATE(LEFT(H11,4),MID(H11,5,2),RIGHT(H11,2)) -> 46025 | M11: =TEXT(L11,"DDDD") -> Saturday | N11: {=_xlfn._xlws.FILTER(Table3[Week '#],(Table3[Start Date]<=Table6[[#This Row],[Date]])*(Table3[End Date]>=Table6[[#This Row],[Date]]),"")} -> Week 1 | P11: P2 | Q11: Week 6 | R11: 46055 | S11: 46061 | T11: 17785.49
B12: P2 | C12: Week 7 | D12: =+E11+1 -> 46062 | E12: =Table3[[#This Row],[Start Date]]+6 -> 46068 | F12: Period 2 | H12: 20260104 | I12: 421022.34 | J12: 1406 | K12: 3316 | L12: =DATE(LEFT(H12,4),MID(H12,5,2),RIGHT(H12,2)) -> 46026 | M12: =TEXT(L12,"DDDD") -> Sunday | N12: {=_xlfn._xlws.FILTER(Table3[Week '#],(Table3[Start Date]<=Table6[[#This Row],[Date]])*(Table3[End Date]>=Table6[[#This Row],[Date]]),"")} -> Week 1 | P12: P2 | Q12: Week 7 | R12: 46062 | S12: 46068 | T12: 19543.79
B13: P2 | C13: Week 8 | D13: =+E12+1 -> 46069 | E13: =Table3[[#This Row],[Start Date]]+6 -> 46075 | F13: Period 3 | H13: 20260105 | I13: 180439.84 | J13: 460 | K13: 1088 | L13: =DATE(LEFT(H13,4),MID(H13,5,2),RIGHT(H13,2)) -> 46027 | M13: =TEXT(L13,"DDDD") -> Monday | N13: {=_xlfn._xlws.FILTER(Table3[Week '#],(Table3[Start Date]<=Table6[[#This Row],[Date]])*(Table3[End Date]>=Table6[[#This Row],[Date]]),"")} -> Week 2 | P13: P2 | Q13: Week 8 | R13: 46069 | S13: 46075 | T13: 14781.81
B14: P3 | C14: Week 9 | D14: =+E13+1 -> 46076 | E14: =Table3[[#This Row],[Start Date]]+6 -> 46082 | F14: Period 3 | H14: 20260106 | I14: 148250.4 | J14: 627 | K14: 1271 | L14: =DATE(LEFT(H14,4),MID(H14,5,2),RIGHT(H14,2)) -> 46028 | M14: =TEXT(L14,"DDDD") -> Tuesday | N14: {=_xlfn._xlws.FILTER(Table3[Week '#],(Table3[Start Date]<=Table6[[#This Row],[Date]])*(Table3[End Date]>=Table6[[#This Row],[Date]]),"")} -> Week 2 | P14: P3 | Q14: Week 9 | R14: 46076 | S14: 46082 | T14: 37196.71
B15: P3 | C15: Week 10 | D15: =+E14+1 -> 46083 | E15: =Table3[[#This Row],[Start Date]]+6 -> 46089 | F15: Period 3 | H15: 20260107 | I15: 304728.96 | J15: 403 | K15: 1357 | L15: =DATE(LEFT(H15,4),MID(H15,5,2),RIGHT(H15,2)) -> 46029 | M15: =TEXT(L15,"DDDD") -> Wednesday | N15: {=_xlfn._xlws.FILTER(Table3[Week '#],(Table3[Start Date]<=Table6[[#This Row],[Date]])*(Table3[End Date]>=Table6[[#This Row],[Date]]),"")} -> Week 2 | P15: P3 | Q15: Week 10 | R15: 46083 | S15: 46089 | T15: 18728.15
B16: P3 | C16: Week 11 | D16: =+E15+1 -> 46090 | E16: =Table3[[#This Row],[Start Date]]+6 -> 46096 | F16: Period 3 | H16: 20260108 | I16: 276687.96 | J16: 1008 | K16: 2498 | L16: =DATE(LEFT(H16,4),MID(H16,5,2),RIGHT(H16,2)) -> 46030 | M16: =TEXT(L16,"DDDD") -> Thursday | N16: {=_xlfn._xlws.FILTER(Table3[Week '#],(Table3[Start Date]<=Table6[[#This Row],[Date]])*(Table3[End Date]>=Table6[[#This Row],[Date]]),"")} -> Week 2 | P16: P3 | Q16: Week 11 | R16: 46090 | S16: 46096 | T16: 54236.2
B17: P3 | C17: Week 12 | D17: =+E16+1 -> 46097 | E17: =Table3[[#This Row],[Start Date]]+6 -> 46103 | F17: Period 3 | H17: 20260109 | I17: 446916.64 | J17: 1702 | K17: 4372 | L17: =DATE(LEFT(H17,4),MID(H17,5,2),RIGHT(H17,2)) -> 46031 | M17: =TEXT(L17,"DDDD") -> Friday | N17: {=_xlfn._xlws.FILTER(Table3[Week '#],(Table3[Start Date]<=Table6[[#This Row],[Date]])*(Table3[End Date]>=Table6[[#This Row],[Date]]),"")} -> Week 2 | P17: P3 | Q17: Week 12 | R17: 46097 | S17: 46103 | T17: 23589.84
B18: P3 | C18: Week 13 | D18: =+E17+1 -> 46104 | E18: =Table3[[#This Row],[Start Date]]+6 -> 46110 | F18: Period 4 | H18: 20260110 | I18: 796057.2 | J18: 2249 | K18: 5255 | L18: =DATE(LEFT(H18,4),MID(H18,5,2),RIGHT(H18,2)) -> 46032 | M18: =TEXT(L18,"DDDD") -> Saturday | N18: {=_xlfn._xlws.FILTER(Table3[Week '#],(Table3[Start Date]<=Table6[[#This Row],[Date]])*(Table3[End Date]>=Table6[[#This Row],[Date]]),"")} -> Week 2 | P18: P3 | Q18: Week 13 | R18: 46104 | S18: 46110 | T18: 13744.82
... B39: P8 | C39: Week 34 | D39: =+E38+1 -> 46251 | E39: =Table3[[#This Row],[Start Date]]+6 -> 46257 | F39: Period 9 | H39: 20260131 | I39: 646873.68 | J39: 2238 | K39: 5396 | L39: =DATE(LEFT(H39,4),MID(H39,5,2),RIGHT(H39,2)) -> 46053 | M39: =TEXT(L39,"DDDD") -> Saturday | N39: {=_xlfn._xlws.FILTER(Table3[Week '#],(Table3[Start Date]<=Table6[[#This Row],[Date]])*(Table3[End Date]>=Table6[[#This Row],[Date]]),"")} -> Week 5 | P39: P8 | Q39: Week 34 | R39: 46251 | S39: 46257 | T39: 5552.87
B40: P9 | C40: Week 35 | D40: =+E39+1 -> 46258 | E40: =Table3[[#This Row],[Start Date]]+6 -> 46264 | F40: Period 9 | H40: 20260201 | I40: 408520.4 | J40: 1293 | K40: 3259 | L40: =DATE(LEFT(H40,4),MID(H40,5,2),RIGHT(H40,2)) -> 46054 | M40: =TEXT(L40,"DDDD") -> Sunday | N40: {=_xlfn._xlws.FILTER(Table3[Week '#],(Table3[Start Date]<=Table6[[#This Row],[Date]])*(Table3[End Date]>=Table6[[#This Row],[Date]]),"")} -> Week 5 | P40: P9 | Q40: Week 35 | R40: 46258 | S40: 46264
B41: P9 | C41: Week 36 | D41: =+E40+1 -> 46265 | E41: =Table3[[#This Row],[Start Date]]+6 -> 46271 | F41: Period 9 | H41: 20260202 | I41: 138461.05 | J41: 365 | K41: 894 | L41: =DATE(LEFT(H41,4),MID(H41,5,2),RIGHT(H41,2)) -> 46055 | M41: =TEXT(L41,"DDDD") -> Monday | N41: {=_xlfn._xlws.FILTER(Table3[Week '#],(Table3[Start Date]<=Table6[[#This Row],[Date]])*(Table3[End Date]>=Table6[[#This Row],[Date]]),"")} -> Week 6 | P41: P9 | Q41: Week 36 | R41: 46265 | S41: 46271
B42: P9 | C42: Week 37 | D42: =+E41+1 -> 46272 | E42: =Table3[[#This Row],[Start Date]]+6 -> 46278 | F42: Period 9 | H42: 20260203 | I42: 265419.65 | J42: 462 | K42: 1539 | L42: =DATE(LEFT(H42,4),MID(H42,5,2),RIGHT(H42,2)) -> 46056 | M42: =TEXT(L42,"DDDD") -> Tuesday | N42: {=_xlfn._xlws.FILTER(Table3[Week '#],(Table3[Start Date]<=Table6[[#This Row],[Date]])*(Table3[End Date]>=Table6[[#This Row],[Date]]),"")} -> Week 6 | P42: P9 | Q42: Week 37 | R42: 46272 | S42: 46278
B43: P9 | C43: Week 38 | D43: =+E42+1 -> 46279 | E43: =Table3[[#This Row],[Start Date]]+6 -> 46285 | F43: Period 9 | H43: 20260204 | I43: 343983.63 | J43: 966 | K43: 2316 | L43: =DATE(LEFT(H43,4),MID(H43,5,2),RIGHT(H43,2)) -> 46057 | M43: =TEXT(L43,"DDDD") -> Wednesday | N43: {=_xlfn._xlws.FILTER(Table3[Week '#],(Table3[Start Date]<=Table6[[#This Row],[Date]])*(Table3[End Date]>=Table6[[#This Row],[Date]]),"")} -> Week 6 | P43: P9 | Q43: Week 38 | R43: 46279 | S43: 46285
B44: P9 | C44: Week 39 | D44: =+E43+1 -> 46286 | E44: =Table3[[#This Row],[Start Date]]+6 -> 46292 | F44: Period 10 | H44: 20260205 | I44: 368173.01 | J44: 1248 | K44: 2747 | L44: =DATE(LEFT(H44,4),MID(H44,5,2),RIGHT(H44,2)) -> 46058 | M44: =TEXT(L44,"DDDD") -> Thursday | N44: {=_xlfn._xlws.FILTER(Table3[Week '#],(Table3[Start Date]<=Table6[[#This Row],[Date]])*(Table3[End Date]>=Table6[[#This Row],[Date]]),"")} -> Week 6 | P44: P9 | Q44: Week 39 | R44: 46286 | S44: 46292
B45: P10 | C45: Week 40 | D45: =+E44+1 -> 46293 | E45: =Table3[[#This Row],[Start Date]]+6 -> 46299 | F45: Period 10 | H45: 20260206 | I45: 525992.3 | J45: 2066 | K45: 4463 | L45: =DATE(LEFT(H45,4),MID(H45,5,2),RIGHT(H45,2)) -> 46059 | M45: =TEXT(L45,"DDDD") -> Friday | N45: {=_xlfn._xlws.FILTER(Table3[Week '#],(Table3[Start Date]<=Table6[[#This Row],[Date]])*(Table3[End Date]>=Table6[[#This Row],[Date]]),"")} -> Week 6 | P45: P10 | Q45: Week 40 | R45: 46293 | S45: 46299
B46: P10 | C46: Week 41 | D46: =+E45+1 -> 46300 | E46: =Table3[[#This Row],[Start Date]]+6 -> 46306 | F46: Period 10 | H46: 20260207 | I46: 677501.44 | J46: 2435 | K46: 5769 | L46: =DATE(LEFT(H46,4),MID(H46,5,2),RIGHT(H46,2)) -> 46060 | M46: =TEXT(L46,"DDDD") -> Saturday | N46: {=_xlfn._xlws.FILTER(Table3[Week '#],(Table3[Start Date]<=Table6[[#This Row],[Date]])*(Table3[End Date]>=Table6[[#This Row],[Date]]),"")} -> Week 6 | P46: P10 | Q46: Week 41 | R46: 46300 | S46: 46306
B47: P10 | C47: Week 42 | D47: =+E46+1 -> 46307 | E47: =Table3[[#This Row],[Start Date]]+6 -> 46313 | F47: Period 10 | H47: 20260208 | I47: 348128.73 | J47: 1160 | K47: 2781 | L47: =DATE(LEFT(H47,4),MID(H47,5,2),RIGHT(H47,2)) -> 46061 | M47: =TEXT(L47,"DDDD") -> Sunday | N47: {=_xlfn._xlws.FILTER(Table3[Week '#],(Table3[Start Date]<=Table6[[#This Row],[Date]])*(Table3[End Date]>=Table6[[#This Row],[Date]]),"")} -> Week 6 | P47: P10 | Q47: Week 42 | R47: 46307 | S47: 46313
B48: P10 | C48: Week 43 | D48: =+E47+1 -> 46314 | E48: =Table3[[#This Row],[Start Date]]+6 -> 46320 | F48: Period 11 | H48: 20260209 | I48: 176290.38 | J48: 463 | K48: 1284 | L48: =DATE(LEFT(H48,4),MID(H48,5,2),RIGHT(H48,2)) -> 46062 | M48: =TEXT(L48,"DDDD") -> Monday | N48: {=_xlfn._xlws.FILTER(Table3[Week '#],(Table3[Start Date]<=Table6[[#This Row],[Date]])*(Table3[End Date]>=Table6[[#This Row],[Date]]),"")} -> Week 7 | P48: P10 | Q48: Week 43 | R48: 46314 | S48: 46320
B49: P11 | C49: Week 44 | D49: =+E48+1 -> 46321 | E49: =Table3[[#This Row],[Start Date]]+6 -> 46327 | F49: Period 11 | H49: 20260210 | I49: 231050.9 | J49: 520 | K49: 1444 | L49: =DATE(LEFT(H49,4),MID(H49,5,2),RIGHT(H49,2)) -> 46063 | M49: =TEXT(L49,"DDDD") -> Tuesday | N49: {=_xlfn._xlws.FILTER(Table3[Week '#],(Table3[Start Date]<=Table6[[#This Row],[Date]])*(Table3[End Date]>=Table6[[#This Row],[Date]]),"")} -> Week 7 | P49: P11 | Q49: Week 44 | R49: 46321 | S49: 46327
B50: P11 | C50: Week 45 | D50: =+E49+1 -> 46328 | E50: =Table3[[#This Row],[Start Date]]+6 -> 46334 | F50: Period 11 | H50: 20260211 | I50: 274089.49 | J50: 869 | K50: 2197 | L50: =DATE(LEFT(H50,4),MID(H50,5,2),RIGHT(H50,2)) -> 46064 | M50: =TEXT(L50,"DDDD") -> Wednesday | N50: {=_xlfn._xlws.FILTER(Table3[Week '#],(Table3[Start Date]<=Table6[[#This Row],[Date]])*(Table3[End Date]>=Table6[[#This Row],[Date]]),"")} -> Week 7 | P50: P11 | Q50: Week 45 | R50: 46328 | S50: 46334
B51: P11 | C51: Week 46 | D51: =+E50+1 -> 46335 | E51: =Table3[[#This Row],[Start Date]]+6 -> 46341 | F51: Period 11 | H51: 20260212 | I51: 386111.41 | J51: 1426 | K51: 3087 | L51: =DATE(LEFT(H51,4),MID(H51,5,2),RIGHT(H51,2)) -> 46065 | M51: =TEXT(L51,"DDDD") -> Thursday | N51: {=_xlfn._xlws.FILTER(Table3[Week '#],(Table3[Start Date]<=Table6[[#This Row],[Date]])*(Table3[End Date]>=Table6[[#This Row],[Date]]),"")} -> Week 7 | P51: P11 | Q51: Week 46 | R51: 46335 | S51: 46341
... B57: P12 | C57: Week 52 | D57: =+E56+1 -> 46377 | E57: =Table3[[#This Row],[Start Date]]+6 -> 46383 | F57: Period 12 | H57: 20260218 | I57: 285714.75 | J57: 947 | K57: 2256 | L57: =DATE(LEFT(H57,4),MID(H57,5,2),RIGHT(H57,2)) -> 46071 | M57: =TEXT(L57,"DDDD") -> Wednesday | N57: {=_xlfn._xlws.FILTER(Table3[Week '#],(Table3[Start Date]<=Table6[[#This Row],[Date]])*(Table3[End Date]>=Table6[[#This Row],[Date]]),"")} -> Week 8 | P57: P12 | Q57: Week 52 | R57: 46377 | S57: 46383
H58: 20260219 | I58: 401170.22 | J58: 1428 | K58: 3067 | L58: =DATE(LEFT(H58,4),MID(H58,5,2),RIGHT(H58,2)) -> 46072 | M58: =TEXT(L58,"DDDD") -> Thursday | N58: {=_xlfn._xlws.FILTER(Table3[Week '#],(Table3[Start Date]<=Table6[[#This Row],[Date]])*(Table3[End Date]>=Table6[[#This Row],[Date]]),"")} -> Week 8
H59: 20260220 | I59: 498937.45 | J59: 1826 | K59: 4178 | L59: =DATE(LEFT(H59,4),MID(H59,5,2),RIGHT(H59,2)) -> 46073 | M59: =TEXT(L59,"DDDD") -> Friday | N59: {=_xlfn._xlws.FILTER(Table3[Week '#],(Table3[Start Date]<=Table6[[#This Row],[Date]])*(Table3[End Date]>=Table6[[#This Row],[Date]]),"")} -> Week 8
H60: 20260221 | I60: 743869.34 | J60: 2360 | K60: 5659 | L60: =DATE(LEFT(H60,4),MID(H60,5,2),RIGHT(H60,2)) -> 46074 | M60: =TEXT(L60,"DDDD") -> Saturday | N60: {=_xlfn._xlws.FILTER(Table3[Week '#],(Table3[Start Date]<=Table6[[#This Row],[Date]])*(Table3[End Date]>=Table6[[#This Row],[Date]]),"")} -> Week 8
H61: 20260222 | I61: 582041.7 | J61: 1794 | K61: 4034 | L61: =DATE(LEFT(H61,4),MID(H61,5,2),RIGHT(H61,2)) -> 46075 | M61: =TEXT(L61,"DDDD") -> Sunday | N61: {=_xlfn._xlws.FILTER(Table3[Week '#],(Table3[Start Date]<=Table6[[#This Row],[Date]])*(Table3[End Date]>=Table6[[#This Row],[Date]]),"")} -> Week 8
H62: 20260223 | I62: 214497.37 | J62: 293 | K62: 873 | L62: =DATE(LEFT(H62,4),MID(H62,5,2),RIGHT(H62,2)) -> 46076 | M62: =TEXT(L62,"DDDD") -> Monday | N62: {=_xlfn._xlws.FILTER(Table3[Week '#],(Table3[Start Date]<=Table6[[#This Row],[Date]])*(Table3[End Date]>=Table6[[#This Row],[Date]]),"")} -> Week 9
H63: 20260224 | I63: 305144.39 | J63: 648 | K63: 1910 | L63: =DATE(LEFT(H63,4),MID(H63,5,2),RIGHT(H63,2)) -> 46077 | M63: =TEXT(L63,"DDDD") -> Tuesday | N63: {=_xlfn._xlws.FILTER(Table3[Week '#],(Table3[Start Date]<=Table6[[#This Row],[Date]])*(Table3[End Date]>=Table6[[#This Row],[Date]]),"")} -> Week 9
H64: 20260225 | I64: 378669.84 | J64: 956 | K64: 2761 | L64: =DATE(LEFT(H64,4),MID(H64,5,2),RIGHT(H64,2)) -> 46078 | M64: =TEXT(L64,"DDDD") -> Wednesday | N64: {=_xlfn._xlws.FILTER(Table3[Week '#],(Table3[Start Date]<=Table6[[#This Row],[Date]])*(Table3[End Date]>=Table6[[#This Row],[Date]]),"")} -> Week 9
H65: 20260226 | I65: 442314.83 | J65: 1283 | K65: 3479 | L65: =DATE(LEFT(H65,4),MID(H65,5,2),RIGHT(H65,2)) -> 46079 | M65: =TEXT(L65,"DDDD") -> Thursday | N65: {=_xlfn._xlws.FILTER(Table3[Week '#],(Table3[Start Date]<=Table6[[#This Row],[Date]])*(Table3[End Date]>=Table6[[#This Row],[Date]]),"")} -> Week 9
H66: 20260227 | I66: 571916.98 | J66: 1865 | K66: 4372 | L66: =DATE(LEFT(H66,4),MID(H66,5,2),RIGHT(H66,2)) -> 46080 | M66: =TEXT(L66,"DDDD") -> Friday | N66: {=_xlfn._xlws.FILTER(Table3[Week '#],(Table3[Start Date]<=Table6[[#This Row],[Date]])*(Table3[End Date]>=Table6[[#This Row],[Date]]),"")} -> Week 9
H67: 20260228 | I67: 783311.22 | J67: 2398 | K67: 5711 | L67: =DATE(LEFT(H67,4),MID(H67,5,2),RIGHT(H67,2)) -> 46081 | M67: =TEXT(L67,"DDDD") -> Saturday | N67: {=_xlfn._xlws.FILTER(Table3[Week '#],(Table3[Start Date]<=Table6[[#This Row],[Date]])*(Table3[End Date]>=Table6[[#This Row],[Date]]),"")} -> Week 9
H68: 20260301 | I68: 571775.35 | J68: 1717 | K68: 4672 | L68: =DATE(LEFT(H68,4),MID(H68,5,2),RIGHT(H68,2)) -> 46082 | M68: =TEXT(L68,"DDDD") -> Sunday | N68: {=_xlfn._xlws.FILTER(Table3[Week '#],(Table3[Start Date]<=Table6[[#This Row],[Date]])*(Table3[End Date]>=Table6[[#This Row],[Date]]),"")} -> Week 9
...

Sheet Actual - 2026
A2: RDG OPS | E2: MILA 3F - 2026 | H2: MILA 3F - 2026 | K2: MILA 3F - 2026 | N2: MILA 2F - 2026 | Q2: MILA 2F - 2026 | T2: MILA 2F - 2026 | W2: MILA 2F - 2026 | Z2: AVA WP - 2026 | AC2: AVA WP - 2026 | AF2: AVA WP - 2026 | AI2: AVA WP - 2025 | AL2: CASA NEOS - 2026 | AO2: CASA NEOS - 2026 | AR2: CASA NEOS - 2026 | AU2: CLAUDIE - 2026 | AX2: CLAUDIE - 2026 | BA2: CLAUDIE - 2026 | BD2: AVA CG - 2026 | BG2: AVA CG - 2026 | BJ2: AVA CG - 2026 | BM2: AVA CG - 2026 | BP2: CASA NEOS LOUNGE - 2026 | BS2: CASA NEOS LOUNGE - 2026 | BV2: CASA NEOS LOUNGE - 2026 | BY2: AVA CG - 2025 | CB2: AVA CG - 2025 | CE2: AVA CG - 2025 | CH2: AVA CG - 2025
E3: Dinner | H3: Brunch | K3: Total | N3: Omakase | Q3: MM | T3: Lounge | W3: Total | Z3: Dinner | AC3: Brunch | AF3: MM | AI3: Total | AL3: Brunch | AO3: Dinner | AR3: Total | AU3: Brunch | AX3: Dinner | BA3: Total | BD3: Dinner | BG3: Brunch | BJ3: MM | BM3: Total | BP3: Lounge | BS3: MM | BV3: Total | BY3: Dinner | CB3: Brunch | CE3: MM | CH3: Total
E4: Sales | F4: Covers | G4: avg ck | H4: Sales | I4: Covers | J4: avg ck | K4: Total Sales | L4: Covers | M4: avg ck | N4: Sales | O4: Covers | P4: avg ck | Q4: Sales | R4: Covers | S4: avg ck | T4: Sales | U4: Covers | V4: avg ck | W4: Total Sales | X4: Covers | Y4: avg ck | Z4: Sales | AA4: Covers | AB4: avg ck | AC4: Sales | AD4: Covers | AE4: avg ck | AF4: Sales | AG4: Covers | AH4: avg ck | AI4: Total Sales | AJ4: Covers | AK4: avg ck | AL4: Sales | AM4: Covers | AN4: avg ck | AO4: Sales | AP4: Covers | AQ4: avg ck | AR4: Total Sales | AS4: Covers | AT4: avg ck | AU4: Sales | AV4: Covers | AW4: avg ck | AX4: Sales | AY4: Covers | AZ4: avg ck | BA4: Total Sales | BB4: Covers | BC4: avg ck | BD4: Sales | BE4: Covers | BF4: avg ck | BG4: Sales | BH4: Covers | BI4: avg ck | BJ4: Sales | BK4: Covers | BL4: avg ck | BM4: Total Sales | BN4: Covers | BO4: avg ck | BP4: Sales | BQ4: Covers | BR4: avg ck | BS4: Sales | BT4: Covers | BU4: avg ck | BV4: Total Sales | BW4: Covers | BX4: avg ck | BY4: Sales | BZ4: Covers | CA4: avg ck | CB4: Sales | CC4: Covers | CD4: avg ck | CE4: Sales | CF4: Covers | CG4: avg ck | CH4: Sales | CI4: Covers | CJ4: avg ck
A5: Week 1 | B5: P1 | C5: =VLOOKUP(A5,Dates!$B$2:$E$53,4,FALSE) -> 1 | D5: =IF(C5<='RDG Weekly Sales'!$F$1,TRUE,FALSE) -> TRUE | E5: =1102583.42-H5-694.45 -> 1054246.3 | F5: =6073-I5 -> 5640 | G5: =IFERROR(E5/F5,"") -> 186.9231 | H5: 47642.7 | I5: 433 | J5: =IFERROR(H5/I5,"") -> 110.02933 | K5: =E5+H5 -> 1101889 | L5: =F5+I5 -> 6073 | M5: =IFERROR(K5/L5,"") -> 181.44063 | N5: 37270 | O5: 94 | P5: =IFERROR(N5/O5,"") -> 396.48936 | Q5: =140722.92+33178 -> 173900.92 | R5: =127+138+2+79+88+130+118+2 -> 684 | S5: =IFERROR(Q5/R5,"") -> 254.24111 | T5: =519097.55+73494-362.61 -> 592228.94 | U5: =258+13+279+17+207+10+223+22+242+18+221+15 -> 1525 | V5: =IFERROR(T5/U5,"") -> 388.34685 | W5: =SUM(N5,Q5,T5) -> 803399.86 | X5: =SUM(O5,R5,U5) -> 2303 | Y5: =IFERROR(W5/X5,"") -> 348.84927 | Z5: =256579.58-AC5-361.6 -> 228189.62 | AA5: =2290-AD5 -> 1916 | AB5: =IFERROR(Z5/AA5,"") -> 119.09688 | AC5: 28028.36 | AD5: =180+194 -> 374 | AE5: =IFERROR(AC5/AD5,"") -> 74.942139 | AF5: =44840.44-521.92 -> 44318.52 | AG5: =57+26+52+69 -> 204 | AH5: =IFERROR(AF5/AG5,"") -> 217.24765 | AI5: =Z5+AF5+AC5 -> 300536.5 | AJ5: =AA5+AG5+AD5 -> 2494 | AK5: =IFERROR(AI5/AJ5,"") -> 120.50381 | AL5: 148498.5 | AM5: =529+573 -> 1102 | AN5: =IFERROR(AL5/AM5,"") -> 134.75363 | AO5: =1639708.27-2309.94-AL5 -> 1488899.8 | AP5: =6146-AM5 -> 5044 | AQ5: =IFERROR(AO5/AP5,"") -> 295.18236 | AR5: =AO5+AL5 -> 1637398.3 | AS5: =AP5+AM5 -> 6146 | AT5: =IFERROR(AR5/AS5,"") -> 266.41691 | AW5: =IFERROR(AU5/AV5,0) -> 0 | AX5: =574241.19-354.85-AU5 -> 573886.34 | AY5: 2831 | AZ5: =IFERROR(AX5/AY5,"") -> 202.71506 | BA5: =AX5+AU5 -> 573886.34 | BB5: =AY5+AV5 -> 2831 | BC5: =IFERROR(BA5/BB5,"") -> 202.71506 | BD5: =258336.81-104.4-BG5-BJ5 -> 245767.89 | BE5: =1726-BH5-BK5 -> 1553 | BF5: =IFERROR(BD5/BE5,"") -> 158.25363 | BG5: 12464.52 | BH5: =87+86 -> 173 | BI5: =IFERROR(BG5/BH5,"") -> 72.049249 | BL5: =IFERROR(BJ5/BK5,"") | BM5: =BD5+BJ5+BG5 -> 258232.41 | BN5: =BE5+BK5+BH5 -> 1726 | BO5: =IFERROR(BM5/BN5,"") -> 149.61322 | BP5: 0 | BQ5: 0 | BR5: =IFERROR(BP5/BQ5,"") | BS5: 0 | BT5: 0 | BU5: =IFERROR(BS5/BT5,"") | BV5: =+BP5+BS5 -> 0 | BW5: =BT5+BQ5 -> 0 | BX5: =IFERROR(BV5/BW5,"") | BY5: 0 | BZ5: 0 | CA5: =IFERROR(BY5/BZ5,"") | CB5: 0 | CC5: 0 | CD5: =IFERROR(CB5/CC5,"") | CG5: =IFERROR(CE5/CF5,"") | CH5: =BY5+CE5+CB5 -> 0 | CI5: =BZ5+CF5+CC5 -> 0 | CJ5: =IFERROR(CH5/CI5,"")
A6: Week 2 | B6: P1 | C6: =VLOOKUP(A6,Dates!$B$2:$E$53,4,FALSE) -> 2 | D6: =IF(C6<='RDG Weekly Sales'!$F$1,TRUE,FALSE) -> TRUE | E6: =880177.35-13716.72-H6-62000 -> 751094.63 | F6: =4397-I6 -> 4056 | G6: =IFERROR(E6/F6,"") -> 185.18112 | H6: 53366 | I6: 341 | J6: =IFERROR(H6/I6,"") -> 156.49853 | K6: =E6+H6 -> 804460.63 | L6: =F6+I6 -> 4397 | M6: =IFERROR(K6/L6,"") -> 182.9567 | N6: 18797 | O6: 66 | P6: =IFERROR(N6/O6,"") -> 284.80303 | Q6: =64479.17+45111 -> 109590.17 | R6: =2+45+104+114 -> 265 | S6: =IFERROR(Q6/R6,"") -> 413.54781 | T6: =201409.35+62707.18-9011.83+62000 -> 317104.7 | U6: =170+193+322+125 -> 810 | V6: =IFERROR(T6/U6,"") -> 391.48728 | W6: =SUM(N6,Q6,T6) -> 445491.87 | X6: =SUM(O6,R6,U6) -> 1141 | Y6: =IFERROR(W6/X6,"") -> 390.43985 | Z6: =192471.13-377.75-AC6 -> 166160.58 | AA6: =1965-AD6 -> 1577 | AB6: =IFERROR(Z6/AA6,"") -> 105.36498 | AC6: 25932.8 | AD6: =191+197 -> 388 | AE6: =IFERROR(AC6/AD6,"") -> 66.837113 | AF6: =25942.65-60.45 -> 25882.2 | AG6: =20+26+32+67+78 -> 223 | AH6: =IFERROR(AF6/AG6,"") -> 116.06368 | AI6: =Z6+AF6+AC6 -> 217975.58 | AJ6: =AA6+AG6+AD6 -> 2188 | AK6: =IFERROR(AI6/AJ6,"") -> 99.623208 | AL6: 158147.86 | AM6: =542+367 -> 909 | AN6: =IFERROR(AL6/AM6,"") -> 173.98004 | AO6: =679288.57-AL6-1727.5 -> 519413.21 | AP6: =3479-AM6 -> 2570 | AQ6: =IFERROR(AO6/AP6,"") -> 202.10631 | AR6: =AO6+AL6 -> 677561.07 | AS6: =AP6+AM6 -> 3479 | AT6: =IFERROR(AR6/AS6,"") -> 194.75742 | AW6: =IFERROR(AU6/AV6,0) -> 0 | AX6: =302340.95-AU6 -> 302340.95 | AY6: 1766 | AZ6: =IFERROR(AX6/AY6,"") -> 171.20099 | BA6: =AX6+AU6 -> 302340.95 | BB6: =AY6+AV6 -> 1766 | BC6: =IFERROR(BA6/BB6,"") -> 171.20099 | BD6: =198817.36-748.7-BG6 -> 184849.07 | BE6: =1562-BH6 -> 1396 | BF6: =IFERROR(BD6/BE6,"") -> 132.41337 | BG6: 13219.59 | BH6: =103+63 -> 166 | BI6: =IFERROR(BG6/BH6,"") -> 79.636084 | BL6: =IFERROR(BJ6/BK6,"") | BM6: =BD6+BJ6+BG6 -> 198068.66 | BN6: =BE6+BK6+BH6 -> 1562 | BO6: =IFERROR(BM6/BN6,"") -> 126.80452 | BP6: 0 | BQ6: 0 | BR6: =IFERROR(BP6/BQ6,"") | BS6: 0 | BT6: 0 | BU6: =IFERROR(BS6/BT6,"") | BV6: =+BP6+BS6 -> 0 | BW6: =BT6+BQ6 -> 0 | BX6: =IFERROR(BV6/BW6,"") | BY6: 0 | BZ6: 0 | CA6: =IFERROR(BY6/BZ6,"") | CB6: 0 | CC6: 0 | CD6: =IFERROR(CB6/CC6,"") | CG6: =IFERROR(CE6/CF6,"") | CH6: =BY6+CE6+CB6 -> 0 | CI6: =BZ6+CF6+CC6 -> 0 | CJ6: =IFERROR(CH6/CI6,"")
