Workbook

Sheet EBIDTA 2
D2: ='[1]Overview 2026'!B24 -> 46025
C4: ='[1]Overview 2026'!J3 -> 9 | D4: =VLOOKUP(D$2,'[1]Overview 2026'!$B$7:$AC$52,$C4,FALSE) -> CLOONEE
B5: DJ Cost | C5: ='[1]Overview 2026'!L3 -> 11 | D5: =VLOOKUP(D$2,'[1]Overview 2026'!$B$7:$AC$52,$C5,FALSE) -> 100000
B6: Dj Cost / Sales Ratio | D6: =IFERROR(D5/D8,"") -> 0.45454545
B8: Brunch Sales | C8: ='[1]Overview 2026'!F3 -> 5 | D8: =D15+D16 -> 220000
B9: Dinner Sales | C9: ='[1]Overview 2026'!H3 -> 7 | D9: =VLOOKUP(D$2,'[1]Overview 2026'!$B$7:$AC$52,$C9,FALSE) -> 101500
B10: Total Sales | D10: =SUM(D8:E9) -> 321500
B11: Budgeted Sales | C11: ='[1]Overview 2026'!D3 -> 3 | D11: =IF(VLOOKUP(D$2,'[1]Overview 2026'!$B6:$AC$52,$C11,FALSE)=0,"",VLOOKUP(D$2,'[1]Overview 2026'!$B6:$AC$52,$C11,FALSE))
B12: Holiday | C12: ='[1]Overview 2026'!C3 -> 2 | D12: =IF(VLOOKUP(D$2,'[1]Overview 2026'!$B7:$AC$52,$C12,FALSE)=0,"",VLOOKUP(D$2,'[1]Overview 2026'!$B7:$AC$52,$C12,FALSE))
B14: Brunch Sales Breakdown
B15: Dining Sales | C15: ='[1]Overview 2026'!F3 -> 5 | D15: =VLOOKUP(D$2,'[1]Overview 2026'!$B7:$AC$52,$C15,FALSE) -> 20000
B16: Bottle Service Sales | C16: ='[1]Overview 2026'!O3 -> 14 | D16: =IFERROR(D5*E16,0) -> 200000 | E16: =VLOOKUP(D$2,'[1]Overview 2026'!$B$7:$AC$52,$C16,FALSE) -> 2
B18: Table Minimum Breakdown
B19: # tables | D19: =E30 -> 28
B20: Avg. Minimum / Table | D20: =D16/D19 -> 7142.8571
C22: ='[1]Overview 2026'!R3 -> 17 | D22: =IF(VLOOKUP(D$2,'[1]Overview 2026'!$B$7:$AC$52,$C22,FALSE)=0,"Beach Club",VLOOKUP(D$2,'[1]Overview 2026'!$B$7:$AC$52,$C22,FALSE)) -> Beach Club
B23: =VLOOKUP(D$22,'[1]Floor Plan Bottle Service'!$R$29:$Y$31,2,FALSE) -> Tier 1 | C23: ='[1]Overview 2026'!W3 -> 22 | D23: =VLOOKUP(D$2,'[1]Overview 2026'!$B$7:$AC$52,$C23,FALSE) -> 11800 | E23: =IF(VLOOKUP(D$22,'[1]Floor Plan Bottle Service'!$R$33:$X$34,2,FALSE)=0,"",VLOOKUP(D$22,'[1]Floor Plan Bottle Service'!$R$33:$X$34,2,FALSE)) -> 3 | G23: =VLOOKUP(H$22,'[1]Floor Plan Bottle Service'!$R$29:$Y$31,2,FALSE) -> #N/A
B24: =VLOOKUP(D$22,'[1]Floor Plan Bottle Service'!$R$29:$Y$31,3,FALSE) -> Tier 2 | C24: ='[1]Overview 2026'!X3 -> 23 | D24: =VLOOKUP(D$2,'[1]Overview 2026'!$B$7:$AC$52,$C24,FALSE) -> 9400 | E24: =VLOOKUP(D$22,'[1]Floor Plan Bottle Service'!$R$33:$Y$34,3,FALSE) -> 2 | G24: =VLOOKUP(H$22,'[1]Floor Plan Bottle Service'!$R$29:$Y$31,3,FALSE) -> #N/A
B25: =VLOOKUP(D$22,'[1]Floor Plan Bottle Service'!$R$29:$Y$31,4,FALSE) -> Tier 3 | C25: ='[1]Overview 2026'!Y3 -> 24 | D25: =VLOOKUP(D$2,'[1]Overview 2026'!$B$7:$AC$52,$C25,FALSE) -> 8200 | E25: =VLOOKUP(D$22,'[1]Floor Plan Bottle Service'!$R$33:$Y$34,4,FALSE) -> 13 | G25: =VLOOKUP(H$22,'[1]Floor Plan Bottle Service'!$R$29:$Y$31,4,FALSE) -> #N/A
B26: =VLOOKUP(D$22,'[1]Floor Plan Bottle Service'!$R$29:$Y$31,5,FALSE) -> Tier 4 | C26: ='[1]Overview 2026'!Z3 -> 25 | D26: =VLOOKUP(D$2,'[1]Overview 2026'!$B$7:$AC$52,$C26,FALSE) -> 5800 | E26: =VLOOKUP(D$22,'[1]Floor Plan Bottle Service'!$R$33:$Y$34,5,FALSE) -> 5 | G26: =VLOOKUP(H$22,'[1]Floor Plan Bottle Service'!$R$29:$Y$31,5,FALSE) -> #N/A
B27: =IF(E27=0,"",VLOOKUP(D$22,'[1]Floor Plan Bottle Service'!$R$29:$Y$31,6,FALSE)) -> Tier 5 | C27: ='[1]Overview 2026'!AA3 -> 26 | D27: =VLOOKUP(D$2,'[1]Overview 2026'!$B$7:$AC$52,$C27,FALSE) -> 3500 | E27: =VLOOKUP(D$22,'[1]Floor Plan Bottle Service'!$R$33:$Y$34,6,FALSE) -> 5 | G27: =IF(I27=0,"",VLOOKUP(H$22,'[1]Floor Plan Bottle Service'!$R$29:$Y$31,6,FALSE))
B28: =IF(E28=0,"",VLOOKUP(D$22,'[1]Floor Plan Bottle Service'!$R$29:$Y$31,7,FALSE)) | C28: ='[1]Overview 2026'!AB3 -> 27 | D28: =VLOOKUP(D$2,'[1]Overview 2026'!$B$7:$AC$52,$C28,FALSE) -> 0 | E28: =VLOOKUP(D$22,'[1]Floor Plan Bottle Service'!$R$33:$Y$34,7,FALSE) -> 0 | G28: =IF(I28=0,"",VLOOKUP(H$22,'[1]Floor Plan Bottle Service'!$R$29:$Y$31,7,FALSE))
B29: =IF(E29=0,"",VLOOKUP(D$22,'[1]Floor Plan Bottle Service'!$R$29:$Y$31,8,FALSE)) | C29: ='[1]Overview 2026'!AC3 -> 28 | D29: =VLOOKUP(D$2,'[1]Overview 2026'!$B$7:$AC$52,$C29,FALSE) -> 0 | E29: =VLOOKUP(D$22,'[1]Floor Plan Bottle Service'!$R$33:$Y$34,8,FALSE) -> 0 | G29: =IF(I29=0,"",VLOOKUP(H$22,'[1]Floor Plan Bottle Service'!$R$29:$Y$31,8,FALSE))
D30: =(D23*E23)+(D24*E24)+(D25*E25)+(D26*E26)+(D27*E27)+(D29*E29)+(D28*E28) -> 207300 | E30: =SUM(E23:E29) -> 28
B33: LBW Sales | D33: =D$36*E33 -> 199330 | E33: 0.62
B34: Food Sales | D34: =D$36*E34 -> 109310 | E34: =E36-E33-E35 -> 0.34
B35: Beverage Sales | D35: =D$36*E35 -> 12860 | E35: 0.04
B36: Total Sales | D36: =D10 -> 321500 | E36: 1
B38: LBW Cost | D38: =E38*D33 -> 29899.5 | E38: 0.15
B39: Food Cost | D39: =E39*D34 -> 28967.15 | E39: 0.265
B40: Beverage Cost | D40: =E40*D35 -> 3600.8 | E40: 0.28
B41: COGS | D41: =SUM(D38:D40) -> 62467.45 | E41: =D41/D36 -> 0.1943
B43: Gross Profit | D43: =D36-D41 -> 259032.55 | E43: =D43/D36 -> 0.8057
B45: Payroll Expenses
B46: Management | D46: ='OPEX DATA 2'!U143 -> 4809.2312 | E46: =D46/D$36 -> 0.014958728
B47: FOH Hourly | D47: ='OPEX DATA 2'!U119 -> 2065.1092 | E47: =D47/D$36 -> 0.0064233569
B48: BOH Hourly | E48: =D48/D$36 -> 0
B49: Payroll Taxes & Other | D49: ='OPEX DATA 2'!U151 -> 2629.4965 | E49: =D49/D$36 -> 0.0081788384
B50: Total Payroll Expenses | D50: =SUM(D46:D49) -> 9503.8369 | E50: =D50/D$36 -> 0.029560924
B52: ='OPEX DATA 2'!A159 -> Direct Operating Expenses
...

Sheet OPEX DATA 2
A1: ` | U1: # Weeks: | V1: =4+4+5 -> 13
K5: Period 4, 2026 | N5: Period 5, 2026 | Q5: PTD 6, 2026 | T5: YTD | U5: Daily Costs
A6: Sales
A7: Food Sales
A8: 4010 - Food Sales | K8: 185418.37 | L8: =IFERROR(K8/K327, "NA") -> 0.20328162 | N8: 273267.01 | O8: =IFERROR(N8/N327, "NA") -> 0.18961866 | Q8: 212103 | R8: =IFERROR(Q8/Q327, "NA") -> 0.19209179 | T8: =IFERROR(B8+E8+H8+K8+N8+Q8, "NA") -> 670788.38 | U8: =(T8/$V$1)/4 -> 12899.777
A9: 4015 - Commissary sales | K9: 0 | L9: =IFERROR(K9/K327, "NA") -> 0 | N9: 0 | O9: =IFERROR(N9/N327, "NA") -> 0 | Q9: 0 | R9: =IFERROR(Q9/Q327, "NA") -> 0 | T9: =IFERROR(B9+E9+H9+K9+N9+Q9, "NA") -> 0 | U9: =(T9/$V$1)/4 -> 0
A10: Total Food Sales | K10: =IFERROR(K8+K9, "NA") -> 185418.37 | L10: =IFERROR(K10/K327, "NA") -> 0.20328162 | N10: =IFERROR(N8+N9, "NA") -> 273267.01 | O10: =IFERROR(N10/N327, "NA") -> 0.18961866 | Q10: =IFERROR(Q8+Q9, "NA") -> 212103 | R10: =IFERROR(Q10/Q327, "NA") -> 0.19209179 | T10: =IFERROR(B10+E10+H10+K10+N10+Q10, "NA") -> 670788.38 | U10: =(T10/$V$1)/4 -> 12899.777
A11: 4020 - N/A Beverage Sales | K11: 33711 | L11: =IFERROR(K11/K327, "NA") -> 0.036958727 | N11: 40376 | O11: =IFERROR(N11/N327, "NA") -> 0.028016711 | Q11: 39938 | R11: =IFERROR(Q11/Q327, "NA") -> 0.036169984 | T11: =IFERROR(B11+E11+H11+K11+N11+Q11, "NA") -> 114025 | U11: =(T11/$V$1)/4 -> 2192.7885
A12: LBW Sales | T12: =IFERROR(B12+E12+H12+K12+N12+Q12, "NA") -> 0 | U12: =(T12/$V$1)/4 -> 0
A13: 4100 - LBW Sales | K13: 0 | L13: =IFERROR(K13/K327, "NA") -> 0 | N13: 0 | O13: =IFERROR(N13/N327, "NA") -> 0 | Q13: 0 | R13: =IFERROR(Q13/Q327, "NA") -> 0 | T13: =IFERROR(B13+E13+H13+K13+N13+Q13, "NA") -> 0 | U13: =(T13/$V$1)/4 -> 0
A14: 4105 - Liquor Sales | K14: 590693 | L14: =IFERROR(K14/K327, "NA") -> 0.64760052 | N14: 816948.21 | O14: =IFERROR(N14/N327, "NA") -> 0.56687642 | Q14: 640884.52 | R14: =IFERROR(Q14/Q327, "NA") -> 0.58041921 | T14: =IFERROR(B14+E14+H14+K14+N14+Q14, "NA") -> 2048525.7 | U14: =(T14/$V$1)/4 -> 39394.726
A15: 4165 - Beer Sales | K15: 5016 | L15: =IFERROR(K15/K327, "NA") -> 0.0054992428 | N15: 6128 | O15: =IFERROR(N15/N327, "NA") -> 0.0042521896 | Q15: 5940 | R15: =IFERROR(Q15/Q327, "NA") -> 0.0053795809 | T15: =IFERROR(B15+E15+H15+K15+N15+Q15, "NA") -> 17084 | U15: =(T15/$V$1)/4 -> 328.53846
A16: 4180 - Wine Sales | K16: 124735 | L16: =IFERROR(K16/K327, "NA") -> 0.136752 | N16: 248408 | O16: =IFERROR(N16/N327, "NA") -> 0.17236911 | Q16: 123330 | R16: =IFERROR(Q16/Q327, "NA") -> 0.11169423 | T16: =IFERROR(B16+E16+H16+K16+N16+Q16, "NA") -> 496473 | U16: =(T16/$V$1)/4 -> 9547.5577
A17: 4181 - Wine BTG Sales | K17: 20799 | L17: =IFERROR(K17/K327, "NA") -> 0.022802781 | N17: 19808 | O17: =IFERROR(N17/N327, "NA") -> 0.013744675 | Q17: 22299 | R17: =IFERROR(Q17/Q327, "NA") -> 0.020195164 | T17: =IFERROR(B17+E17+H17+K17+N17+Q17, "NA") -> 62906 | U17: =(T17/$V$1)/4 -> 1209.7308
A18: 4182 - Wine Reserve Sales | K18: 0 | L18: =IFERROR(K18/K327, "NA") -> 0 | N18: 0 | O18: =IFERROR(N18/N327, "NA") -> 0 | Q18: 0 | R18: =IFERROR(Q18/Q327, "NA") -> 0 | T18: =IFERROR(B18+E18+H18+K18+N18+Q18, "NA") -> 0 | U18: =(T18/$V$1)/4 -> 0
A19: Total LBW Sales | K19: =IFERROR(K13+K14+K15+K16+K17+K18, "NA") -> 741243 | L19: =IFERROR(K19/K327, "NA") -> 0.81265455 | N19: =IFERROR(N13+N14+N15+N16+N17+N18, "NA") -> 1091292.2 | O19: =IFERROR(N19/N327, "NA") -> 0.75724239 | Q19: =IFERROR(Q13+Q14+Q15+Q16+Q17+Q18, "NA") -> 792453.52 | R19: =IFERROR(Q19/Q327, "NA") -> 0.71768819 | T19: =IFERROR(B19+E19+H19+K19+N19+Q19, "NA") -> 2624988.7 | U19: =(T19/$V$1)/4 -> 50480.552
A20: Other Sales | T20: =IFERROR(B20+E20+H20+K20+N20+Q20, "NA") -> 0 | U20: =(T20/$V$1)/4 -> 0
A21: 4209 - Other Sales | K21: 0 | L21: =IFERROR(K21/K327, "NA") -> 0 | N21: 0 | O21: =IFERROR(N21/N327, "NA") -> 0 | Q21: 0 | R21: =IFERROR(Q21/Q327, "NA") -> 0 | T21: =IFERROR(B21+E21+H21+K21+N21+Q21, "NA") -> 0 | U21: =(T21/$V$1)/4 -> 0
A22: 4210 - Retail Sales | K22: 15485.86 | L22: =IFERROR(K22/K327, "NA") -> 0.016977772 | N22: 30095.36 | O22: =IFERROR(N22/N327, "NA") -> 0.020883025 | Q22: 33235.43 | R22: =IFERROR(Q22/Q327, "NA") -> 0.030099779 | T22: =IFERROR(B22+E22+H22+K22+N22+Q22, "NA") -> 78816.65 | U22: =(T22/$V$1)/4 -> 1515.7048
A23: 4211 - No show / Min not met | K23: 412 | L23: =IFERROR(K23/K327, "NA") -> 0.00045169219 | N23: 0 | O23: =IFERROR(N23/N327, "NA") -> 0 | Q23: 886.11 | R23: =IFERROR(Q23/Q327, "NA") -> 0.00080250849 | T23: =IFERROR(B23+E23+H23+K23+N23+Q23, "NA") -> 1298.11 | U23: =(T23/$V$1)/4 -> 24.963654
A24: 4215 - Yacht sales | K24: 0 | L24: =IFERROR(K24/K327, "NA") -> 0 | N24: 0 | O24: =IFERROR(N24/N327, "NA") -> 0 | Q24: 0 | R24: =IFERROR(Q24/Q327, "NA") -> 0 | T24: =IFERROR(B24+E24+H24+K24+N24+Q24, "NA") -> 0 | U24: =(T24/$V$1)/4 -> 0
A25: 4216 - Docking fees Revenue | K25: 0 | L25: =IFERROR(K25/K327, "NA") -> 0 | N25: 0 | O25: =IFERROR(N25/N327, "NA") -> 0 | Q25: 0 | R25: =IFERROR(Q25/Q327, "NA") -> 0 | T25: =IFERROR(B25+E25+H25+K25+N25+Q25, "NA") -> 0 | U25: =(T25/$V$1)/4 -> 0
A26: 4220 - Membership Revenue | K26: 0 | L26: =IFERROR(K26/K327, "NA") -> 0 | N26: 62421.3 | O26: =IFERROR(N26/N327, "NA") -> 0.043313838 | Q26: 81567.48 | R26: =IFERROR(Q26/Q327, "NA") -> 0.073871862 | T26: =IFERROR(B26+E26+H26+K26+N26+Q26, "NA") -> 143988.78 | U26: =(T26/$V$1)/4 -> 2769.015
A27: 4221 - Application Fee Revenue | K27: 0 | L27: =IFERROR(K27/K327, "NA") -> 0 | N27: 0 | O27: =IFERROR(N27/N327, "NA") -> 0 | Q27: 0 | R27: =IFERROR(Q27/Q327, "NA") -> 0 | T27: =IFERROR(B27+E27+H27+K27+N27+Q27, "NA") -> 0 | U27: =(T27/$V$1)/4 -> 0
A28: 4230 - Retained Service Charge | K28: 0 | L28: =IFERROR(K28/K327, "NA") -> 0 | N28: 0 | O28: =IFERROR(N28/N327, "NA") -> 0 | Q28: 0 | R28: =IFERROR(Q28/Q327, "NA") -> 0 | T28: =IFERROR(B28+E28+H28+K28+N28+Q28, "NA") -> 0 | U28: =(T28/$V$1)/4 -> 0
A29: 4250 - Service Sales | K29: 0 | L29: =IFERROR(K29/K327, "NA") -> 0 | N29: 0 | O29: =IFERROR(N29/N327, "NA") -> 0 | Q29: 0 | R29: =IFERROR(Q29/Q327, "NA") -> 0 | T29: =IFERROR(B29+E29+H29+K29+N29+Q29, "NA") -> 0 | U29: =(T29/$V$1)/4 -> 0
A30: Total Other Sales | K30: =IFERROR(K21+K22+K23+K24+K25+K26+K27+K28+K29, "NA") -> 15897.86 | L30: =IFERROR(K30/K327, "NA") -> 0.017429464 | N30: =IFERROR(N21+N22+N23+N24+N25+N26+N27+N28+N29, "NA") -> 92516.66 | O30: =IFERROR(N30/N327, "NA") -> 0.064196863 | Q30: =IFERROR(Q21+Q22+Q23+Q24+Q25+Q26+Q27+Q28+Q29, "NA") -> 115689.02 | R30: =IFERROR(Q30/Q327, "NA") -> 0.10477415 | T30: =IFERROR(B30+E30+H30+K30+N30+Q30, "NA") -> 224103.54 | U30: =(T30/$V$1)/4 -> 4309.6835
A31: Hotel Sales | T31: =IFERROR(B31+E31+H31+K31+N31+Q31, "NA") -> 0 | U31: =(T31/$V$1)/4 -> 0
A32: 4399 - Hotel Sales | K32: 0 | L32: =IFERROR(K32/K327, "NA") -> 0 | N32: 0 | O32: =IFERROR(N32/N327, "NA") -> 0 | Q32: 0 | R32: =IFERROR(Q32/Q327, "NA") -> 0 | T32: =IFERROR(B32+E32+H32+K32+N32+Q32, "NA") -> 0 | U32: =(T32/$V$1)/4 -> 0
A33: 4301 - Accommodation | K33: 0 | L33: =IFERROR(K33/K327, "NA") -> 0 | N33: 0 | O33: =IFERROR(N33/N327, "NA") -> 0 | Q33: 0 | R33: =IFERROR(Q33/Q327, "NA") -> 0 | T33: =IFERROR(B33+E33+H33+K33+N33+Q33, "NA") -> 0 | U33: =(T33/$V$1)/4 -> 0
A34: 4310 - Mini Bar | K34: 0 | L34: =IFERROR(K34/K327, "NA") -> 0 | N34: 0 | O34: =IFERROR(N34/N327, "NA") -> 0 | Q34: 0 | R34: =IFERROR(Q34/Q327, "NA") -> 0 | T34: =IFERROR(B34+E34+H34+K34+N34+Q34, "NA") -> 0 | U34: =(T34/$V$1)/4 -> 0
A35: 4320 - Destination Fee | K35: 0 | L35: =IFERROR(K35/K327, "NA") -> 0 | N35: 0 | O35: =IFERROR(N35/N327, "NA") -> 0 | Q35: 0 | R35: =IFERROR(Q35/Q327, "NA") -> 0 | T35: =IFERROR(B35+E35+H35+K35+N35+Q35, "NA") -> 0 | U35: =(T35/$V$1)/4 -> 0
A36: 4340 - Other Accommodation | K36: 0 | L36: =IFERROR(K36/K327, "NA") -> 0 | N36: 0 | O36: =IFERROR(N36/N327, "NA") -> 0 | Q36: 0 | R36: =IFERROR(Q36/Q327, "NA") -> 0 | T36: =IFERROR(B36+E36+H36+K36+N36+Q36, "NA") -> 0 | U36: =(T36/$V$1)/4 -> 0
A37: Total Hotel Sales | K37: =IFERROR(K32+K33+K34+K35+K36, "NA") -> 0 | L37: =IFERROR(K37/K327, "NA") -> 0 | N37: =IFERROR(N32+N33+N34+N35+N36, "NA") -> 0 | O37: =IFERROR(N37/N327, "NA") -> 0 | Q37: =IFERROR(Q32+Q33+Q34+Q35+Q36, "NA") -> 0 | R37: =IFERROR(Q37/Q327, "NA") -> 0 | T37: =IFERROR(B37+E37+H37+K37+N37+Q37, "NA") -> 0 | U37: =(T37/$V$1)/4 -> 0
A38: Comps & Promotions | T38: =IFERROR(B38+E38+H38+K38+N38+Q38, "NA") -> 0 | U38: =(T38/$V$1)/4 -> 0
A39: 4900 - Comps & Promotions | K39: 0 | L39: =IFERROR(K39/K327, "NA") -> 0 | N39: 0 | O39: =IFERROR(N39/N327, "NA") -> 0 | Q39: 0 | R39: =IFERROR(Q39/Q327, "NA") -> 0 | T39: =IFERROR(B39+E39+H39+K39+N39+Q39, "NA") -> 0 | U39: =(T39/$V$1)/4 -> 0
A40: 4910 - Employee Discount | K40: -88.25 | L40: =IFERROR(K40/K327, "NA") -> -9.6752028e-05 | N40: -132.75 | O40: =IFERROR(N40/N327, "NA") -> -9.2114584e-05 | Q40: -148.5 | R40: =IFERROR(Q40/Q327, "NA") -> -0.00013448952 | T40: =IFERROR(B40+E40+H40+K40+N40+Q40, "NA") -> -369.5 | U40: =(T40/$V$1)/4 -> -7.1057692
A41: 4915 - Manager Meal | K41: -1187 | L41: =IFERROR(K41/K327, "NA") -> -0.0013013559 | N41: -929 | O41: =IFERROR(N41/N327, "NA") -> -0.00064462861 | Q41: -1884 | R41: =IFERROR(Q41/Q327, "NA") -> -0.0017062509 | T41: =IFERROR(B41+E41+H41+K41+N41+Q41, "NA") -> -4000 | U41: =(T41/$V$1)/4 -> -76.923077
A42: 4920 - Positive Comp | K42: -3451 | L42: =IFERROR(K42/K327, "NA") -> -0.0037834703 | N42: -3002 | O42: =IFERROR(N42/N327, "NA") -> -0.0020830733 | Q42: -4067 | R42: =IFERROR(Q42/Q327, "NA") -> -0.0036832922 | T42: =IFERROR(B42+E42+H42+K42+N42+Q42, "NA") -> -10520 | U42: =(T42/$V$1)/4 -> -202.30769
A43: 4924 - Marketing/Promotions | K43: -12703 | L43: =IFERROR(K43/K327, "NA") -> -0.01392681 | N43: -18620.04 | O43: =IFERROR(N43/N327, "NA") -> -0.012920356 | Q43: -24439.41 | R43: =IFERROR(Q43/Q327, "NA") -> -0.022133634 | T43: =IFERROR(B43+E43+H43+K43+N43+Q43, "NA") -> -55762.45 | U43: =(T43/$V$1)/4 -> -1072.3548
...
