Workbook

Sheet EBIDTA 2
D2: ='[1]Overview 2026'!B24 -> 46025
C4: ='[1]Overview 2026'!J3 -> 9 | D4: =VLOOKUP(D$2,'[1]Overview 2026'!$B$7:$AC$52,$C4,FALSE) -> CLOONEE
B5: DJ Cost | C5: ='[1]Overview 2026'!L3 -> 11 | D5: 4000
B6: Dj Cost / Sales Ratio | D6: =IFERROR(D5/D8,"") -> 0.14285714
B8: Brunch Sales | C8: ='[1]Overview 2026'!F3 -> 5 | D8: =D15+D16 -> 28000 | T8: =IFERROR(B8+E8+H8+K8+N8+Q8, "NA") -> NA
B9: Dinner Sales | C9: ='[1]Overview 2026'!H3 -> 7 | D9: =VLOOKUP(D$2,'[1]Overview 2026'!$B$7:$AC$52,$C9,FALSE) -> 101500 | W9: =4+4+5 -> 13
B10: Total Sales | D10: 61500 | W10: =W9*2 -> 26
B11: Budgeted Sales | C11: ='[1]Overview 2026'!D3 -> 3 | D11: =IF(VLOOKUP(D$2,'[1]Overview 2026'!$B6:$AC$52,$C11,FALSE)=0,"",VLOOKUP(D$2,'[1]Overview 2026'!$B6:$AC$52,$C11,FALSE))
B12: Holiday | C12: ='[1]Overview 2026'!C3 -> 2 | D12: =IF(VLOOKUP(D$2,'[1]Overview 2026'!$B7:$AC$52,$C12,FALSE)=0,"",VLOOKUP(D$2,'[1]Overview 2026'!$B7:$AC$52,$C12,FALSE))
B14: Brunch Sales Breakdown
B15: Dining Sales | C15: ='[1]Overview 2026'!F3 -> 5 | D15: =VLOOKUP(D$2,'[1]Overview 2026'!$B7:$AC$52,$C15,FALSE) -> 20000
B16: Bottle Service Sales | C16: ='[1]Overview 2026'!O3 -> 14 | D16: =IFERROR(D5*E16,0) -> 8000 | E16: =VLOOKUP(D$2,'[1]Overview 2026'!$B$7:$AC$52,$C16,FALSE) -> 2
B18: Table Minimum Breakdown
B19: # tables | D19: =E30 -> 28
B20: Avg. Minimum / Table | D20: =D16/D19 -> 285.71429
C22: ='[1]Overview 2026'!R3 -> 17 | D22: =IF(VLOOKUP(D$2,'[1]Overview 2026'!$B$7:$AC$52,$C22,FALSE)=0,"Beach Club",VLOOKUP(D$2,'[1]Overview 2026'!$B$7:$AC$52,$C22,FALSE)) -> Beach Club
B23: =VLOOKUP(D$22,'[1]Floor Plan Bottle Service'!$R$29:$Y$31,2,FALSE) -> Tier 1 | C23: ='[1]Overview 2026'!W3 -> 22 | D23: =VLOOKUP(D$2,'[1]Overview 2026'!$B$7:$AC$52,$C23,FALSE) -> 11800 | E23: =IF(VLOOKUP(D$22,'[1]Floor Plan Bottle Service'!$R$33:$X$34,2,FALSE)=0,"",VLOOKUP(D$22,'[1]Floor Plan Bottle Service'!$R$33:$X$34,2,FALSE)) -> 3 | G23: =VLOOKUP(H$22,'[1]Floor Plan Bottle Service'!$R$29:$Y$31,2,FALSE) -> #N/A
B24: =VLOOKUP(D$22,'[1]Floor Plan Bottle Service'!$R$29:$Y$31,3,FALSE) -> Tier 2 | C24: ='[1]Overview 2026'!X3 -> 23 | D24: =VLOOKUP(D$2,'[1]Overview 2026'!$B$7:$AC$52,$C24,FALSE) -> 9400 | E24: =VLOOKUP(D$22,'[1]Floor Plan Bottle Service'!$R$33:$Y$34,3,FALSE) -> 2 | G24: =VLOOKUP(H$22,'[1]Floor Plan Bottle Service'!$R$29:$Y$31,3,FALSE) -> #N/A
B25: =VLOOKUP(D$22,'[1]Floor Plan Bottle Service'!$R$29:$Y$31,4,FALSE) -> Tier 3 | C25: ='[1]Overview 2026'!Y3 -> 24 | D25: =VLOOKUP(D$2,'[1]Overview 2026'!$B$7:$AC$52,$C25,FALSE) -> 8200 | E25: =VLOOKUP(D$22,'[1]Floor Plan Bottle Service'!$R$33:$Y$34,4,FALSE) -> 13 | G25: =VLOOKUP(H$22,'[1]Floor Plan Bottle Service'!$R$29:$Y$31,4,FALSE) -> #N/A
B26: =VLOOKUP(D$22,'[1]Floor Plan Bottle Service'!$R$29:$Y$31,5,FALSE) -> Tier 4 | C26: ='[1]Overview 2026'!Z3 -> 25 | D26: =VLOOKUP(D$2,'[1]Overview 2026'!$B$7:$AC$52,$C26,FALSE) -> 5800 | E26: =VLOOKUP(D$22,'[1]Floor Plan Bottle Service'!$R$33:$Y$34,5,FALSE) -> 5 | G26: =VLOOKUP(H$22,'[1]Floor Plan Bottle Service'!$R$29:$Y$31,5,FALSE) -> #N/A
B27: =IF(E27=0,"",VLOOKUP(D$22,'[1]Floor Plan Bottle Service'!$R$29:$Y$31,6,FALSE)) -> Tier 5 | C27: ='[1]Overview 2026'!AA3 -> 26 | D27: =VLOOKUP(D$2,'[1]Overview 2026'!$B$7:$AC$52,$C27,FALSE) -> 3500 | E27: =VLOOKUP(D$22,'[1]Floor Plan Bottle Service'!$R$33:$Y$34,6,FALSE) -> 5 | G27: =IF(I27=0,"",VLOOKUP(H$22,'[1]Floor Plan Bottle Service'!$R$29:$Y$31,6,FALSE))
B28: =IF(E28=0,"",VLOOKUP(D$22,'[1]Floor Plan Bottle Service'!$R$29:$Y$31,7,FALSE)) | C28: ='[1]Overview 2026'!AB3 -> 27 | D28: =VLOOKUP(D$2,'[1]Overview 2026'!$B$7:$AC$52,$C28,FALSE) -> 0 | E28: =VLOOKUP(D$22,'[1]Floor Plan Bottle Service'!$R$33:$Y$34,7,FALSE) -> 0 | G28: =IF(I28=0,"",VLOOKUP(H$22,'[1]Floor Plan Bottle Service'!$R$29:$Y$31,7,FALSE))
B29: =IF(E29=0,"",VLOOKUP(D$22,'[1]Floor Plan Bottle Service'!$R$29:$Y$31,8,FALSE)) | C29: ='[1]Overview 2026'!AC3 -> 28 | D29: =VLOOKUP(D$2,'[1]Overview 2026'!$B$7:$AC$52,$C29,FALSE) -> 0 | E29: =VLOOKUP(D$22,'[1]Floor Plan Bottle Service'!$R$33:$Y$34,8,FALSE) -> 0 | G29: =IF(I29=0,"",VLOOKUP(H$22,'[1]Floor Plan Bottle Service'!$R$29:$Y$31,8,FALSE))
D30: =(D23*E23)+(D24*E24)+(D25*E25)+(D26*E26)+(D27*E27)+(D29*E29)+(D28*E28) -> 207300 | E30: =SUM(E23:E29) -> 28
B33: LBW Sales | D33: =D$36*E33 -> 38130 | E33: 0.62
B34: Food Sales | D34: =D$36*E34 -> 20910 | E34: =E36-E33-E35 -> 0.34
B35: Beverage Sales | D35: =D$36*E35 -> 2460 | E35: 0.04
B36: Total Sales | D36: =D10 -> 61500 | E36: 1
B38: LBW Cost | D38: =E38*D33 -> 5719.5 | E38: 0.15
B39: Food Cost | D39: =E39*D34 -> 5541.15 | E39: 0.265
B40: Beverage Cost | D40: =E40*D35 -> 688.8 | E40: 0.28
B41: COGS | D41: =SUM(D38:D40) -> 11949.45 | E41: =D41/D36 -> 0.1943
B43: Gross Profit | D43: =D36-D41 -> 49550.55 | E43: =D43/D36 -> 0.8057
B45: Payroll Expenses
B46: Management | D46: ='OPEX DATA 2'!U139+'OPEX DATA 2'!U141+'OPEX DATA 2'!U142 -> 4344.7518 | E46: =D46/D$36 -> 0.070646371
B47: FOH Hourly | D47: ='OPEX DATA 2'!U123+'OPEX DATA 2'!U97+'OPEX DATA 2'!U98+'OPEX DATA 2'!U110+'OPEX DATA 2'!U112 -> 1423.4991 | E47: =D47/D$36 -> 0.023146327
B48: BOH Hourly | D48: ='OPEX DATA 2'!U85+'OPEX DATA 2'!U86+'OPEX DATA 2'!U87+'OPEX DATA 2'!U88+'OPEX DATA 2'!U92+'OPEX DATA 2'!U124 -> 3049.3579 | E48: =D48/D$36 -> 0.049583055
B49: Payroll Taxes & Other | D49: ='OPEX DATA 2'!U151+'OPEX DATA 2'!U153+'OPEX DATA 2'!U154 -> 2499.9872 | E49: =D49/D$36 -> 0.040650198
B50: Total Payroll Expenses | D50: =SUM(D46:D49) -> 11317.596 | E50: =D50/D$36 -> 0.18402595
B52: ='OPEX DATA 2'!A159 -> Direct Operating Expenses
...

Sheet OPEX DATA 2
A1: ` | U1: # Weeks: | V1: 26
B5: Period 1, 2026 | E5: Period 2, 2026 | H5: Period 3, 2026 | K5: Period 4, 2026 | N5: Period 5, 2026 | Q5: Period 6, 2026 | T5: YTD | U5: Daily Costs
A6: Sales
A7: Food Sales
A8: 4010 - Food Sales | B8: 572516.55 | C8: =IFERROR(B8/B327, "NA") -> 0.2583052 | E8: 470187 | F8: =IFERROR(E8/E327, "NA") -> 0.26723839 | H8: 697656.3 | I8: =IFERROR(H8/H327, "NA") -> 0.28507415 | K8: 395561 | L8: =IFERROR(K8/K327, "NA") -> 0.26112304 | N8: 596937.21 | O8: =IFERROR(N8/N327, "NA") -> 0.28237076 | Q8: 385651 | R8: =IFERROR(Q8/Q327, "NA") -> 0.27800031 | T8: =IFERROR(B8+E8+H8+K8+N8+Q8, "NA") -> 3118509.1 | U8: =(T8/$V$1)/7 -> 17134.665
A9: 4015 - Commissary sales | B9: 0 | C9: =IFERROR(B9/B327, "NA") -> 0 | E9: 0 | F9: =IFERROR(E9/E327, "NA") -> 0 | H9: 0 | I9: =IFERROR(H9/H327, "NA") -> 0 | K9: 0 | L9: =IFERROR(K9/K327, "NA") -> 0 | N9: 0 | O9: =IFERROR(N9/N327, "NA") -> 0 | Q9: 0 | R9: =IFERROR(Q9/Q327, "NA") -> 0 | T9: =IFERROR(B9+E9+H9+K9+N9+Q9, "NA") -> 0 | U9: =(T9/$V$1)/7 -> 0 | W9: =4+4+5 -> 13
A10: Total Food Sales | B10: =IFERROR(B8+B9, "NA") -> 572516.55 | C10: =IFERROR(B10/B327, "NA") -> 0.2583052 | E10: =IFERROR(E8+E9, "NA") -> 470187 | F10: =IFERROR(E10/E327, "NA") -> 0.26723839 | H10: =IFERROR(H8+H9, "NA") -> 697656.3 | I10: =IFERROR(H10/H327, "NA") -> 0.28507415 | K10: =IFERROR(K8+K9, "NA") -> 395561 | L10: =IFERROR(K10/K327, "NA") -> 0.26112304 | N10: =IFERROR(N8+N9, "NA") -> 596937.21 | O10: =IFERROR(N10/N327, "NA") -> 0.28237076 | Q10: =IFERROR(Q8+Q9, "NA") -> 385651 | R10: =IFERROR(Q10/Q327, "NA") -> 0.27800031 | T10: =IFERROR(B10+E10+H10+K10+N10+Q10, "NA") -> 3118509.1 | U10: =(T10/$V$1)/7 -> 17134.665 | W10: =W9*2 -> 26
A11: 4020 - N/A Beverage Sales | B11: 70391 | C11: =IFERROR(B11/B327, "NA") -> 0.031758665 | E11: 53929 | F11: =IFERROR(E11/E327, "NA") -> 0.03065142 | H11: 75086.53 | I11: =IFERROR(H11/H327, "NA") -> 0.030681625 | K11: 52783.51 | L11: =IFERROR(K11/K327, "NA") -> 0.03484416 | N11: 65238 | O11: =IFERROR(N11/N327, "NA") -> 0.030859701 | Q11: 51065 | R11: =IFERROR(Q11/Q327, "NA") -> 0.036810707 | T11: =IFERROR(B11+E11+H11+K11+N11+Q11, "NA") -> 368493.04 | U11: =(T11/$V$1)/7 -> 2024.687
A12: LBW Sales | T12: =IFERROR(B12+E12+H12+K12+N12+Q12, "NA") -> 0 | U12: =(T12/$V$1)/7 -> 0
A13: 4100 - LBW Sales | B13: 0 | C13: =IFERROR(B13/B327, "NA") -> 0 | E13: 0 | F13: =IFERROR(E13/E327, "NA") -> 0 | H13: 0 | I13: =IFERROR(H13/H327, "NA") -> 0 | K13: 0 | L13: =IFERROR(K13/K327, "NA") -> 0 | N13: 0 | O13: =IFERROR(N13/N327, "NA") -> 0 | Q13: 0 | R13: =IFERROR(Q13/Q327, "NA") -> 0 | T13: =IFERROR(B13+E13+H13+K13+N13+Q13, "NA") -> 0 | U13: =(T13/$V$1)/7 -> 0
A14: 4105 - Liquor Sales | B14: 1090650 | C14: =IFERROR(B14/B327, "NA") -> 0.4920741 | E14: 830839 | F14: =IFERROR(E14/E327, "NA") -> 0.4722208 | H14: 1166419 | I14: =IFERROR(H14/H327, "NA") -> 0.47661852 | K14: 722390 | L14: =IFERROR(K14/K327, "NA") -> 0.4768738 | N14: 940974.71 | O14: =IFERROR(N14/N327, "NA") -> 0.44511171 | Q14: 677135 | R14: =IFERROR(Q14/Q327, "NA") -> 0.48811941 | T14: =IFERROR(B14+E14+H14+K14+N14+Q14, "NA") -> 5428407.7 | U14: =(T14/$V$1)/7 -> 29826.416
A15: 4165 - Beer Sales | B15: 10518 | C15: =IFERROR(B15/B327, "NA") -> 0.0047454595 | E15: 8634 | F15: =IFERROR(E15/E327, "NA") -> 0.0049072737 | H15: 13368 | I15: =IFERROR(H15/H327, "NA") -> 0.0054623907 | K15: 7233 | L15: =IFERROR(K15/K327, "NA") -> 0.0047747452 | N15: 8969 | O15: =IFERROR(N15/N327, "NA") -> 0.0042426294 | Q15: 5467 | R15: =IFERROR(Q15/Q327, "NA") -> 0.0039409406 | T15: =IFERROR(B15+E15+H15+K15+N15+Q15, "NA") -> 54189 | U15: =(T15/$V$1)/7 -> 297.74176
A16: 4180 - Wine Sales | B16: 197139 | C16: =IFERROR(B16/B327, "NA") -> 0.088944204 | E16: 175759 | F16: =IFERROR(E16/E327, "NA") -> 0.099895473 | H16: 256346 | I16: =IFERROR(H16/H327, "NA") -> 0.10474731 | K16: 166595 | L16: =IFERROR(K16/K327, "NA") -> 0.10997493 | N16: 303542 | O16: =IFERROR(N16/N327, "NA") -> 0.14358526 | Q16: 145189 | R16: =IFERROR(Q16/Q327, "NA") -> 0.10466092 | T16: =IFERROR(B16+E16+H16+K16+N16+Q16, "NA") -> 1244570 | U16: =(T16/$V$1)/7 -> 6838.2967
A17: 4181 - Wine BTG Sales | B17: 45936 | C17: =IFERROR(B17/B327, "NA") -> 0.020725178 | E17: 53549 | F17: =IFERROR(E17/E327, "NA") -> 0.030435441 | H17: 51850 | I17: =IFERROR(H17/H327, "NA") -> 0.021186786 | K17: 34556 | L17: =IFERROR(K17/K327, "NA") -> 0.022811571 | N17: 41151 | O17: =IFERROR(N17/N327, "NA") -> 0.019465764 | Q17: 28108 | R17: =IFERROR(Q17/Q327, "NA") -> 0.020261928 | T17: =IFERROR(B17+E17+H17+K17+N17+Q17, "NA") -> 255150 | U17: =(T17/$V$1)/7 -> 1401.9231
A18: 4182 - Wine Reserve Sales | B18: 135005 | C18: =IFERROR(B18/B327, "NA") -> 0.060910891 | E18: 88110 | F18: =IFERROR(E18/E327, "NA") -> 0.050078745 | H18: 127530 | I18: =IFERROR(H18/H327, "NA") -> 0.052110913 | K18: 79700 | L18: =IFERROR(K18/K327, "NA") -> 0.052612635 | N18: 61455 | O18: =IFERROR(N18/N327, "NA") -> 0.029070218 | Q18: 71370 | R18: =IFERROR(Q18/Q327, "NA") -> 0.051447765 | T18: =IFERROR(B18+E18+H18+K18+N18+Q18, "NA") -> 563170 | U18: =(T18/$V$1)/7 -> 3094.3407
A19: Total LBW Sales | B19: =IFERROR(B13+B14+B15+B16+B17+B18, "NA") -> 1479248 | C19: =IFERROR(B19/B327, "NA") -> 0.66739983 | E19: =IFERROR(E13+E14+E15+E16+E17+E18, "NA") -> 1156891 | F19: =IFERROR(E19/E327, "NA") -> 0.65753773 | H19: =IFERROR(H13+H14+H15+H16+H17+H18, "NA") -> 1615513 | I19: =IFERROR(H19/H327, "NA") -> 0.66012591 | K19: =IFERROR(K13+K14+K15+K16+K17+K18, "NA") -> 1010474 | L19: =IFERROR(K19/K327, "NA") -> 0.66704768 | N19: =IFERROR(N13+N14+N15+N16+N17+N18, "NA") -> 1356091.7 | O19: =IFERROR(N19/N327, "NA") -> 0.64147559 | Q19: =IFERROR(Q13+Q14+Q15+Q16+Q17+Q18, "NA") -> 927269 | R19: =IFERROR(Q19/Q327, "NA") -> 0.66843096 | T19: =IFERROR(B19+E19+H19+K19+N19+Q19, "NA") -> 7545486.7 | U19: =(T19/$V$1)/7 -> 41458.718
A20: Other Sales | T20: =IFERROR(B20+E20+H20+K20+N20+Q20, "NA") -> 0 | U20: =(T20/$V$1)/7 -> 0
A21: 4209 - Other Sales | B21: 0 | C21: =IFERROR(B21/B327, "NA") -> 0 | E21: 0 | F21: =IFERROR(E21/E327, "NA") -> 0 | H21: 0 | I21: =IFERROR(H21/H327, "NA") -> 0 | K21: 0 | L21: =IFERROR(K21/K327, "NA") -> 0 | N21: 0 | O21: =IFERROR(N21/N327, "NA") -> 0 | Q21: 0 | R21: =IFERROR(Q21/Q327, "NA") -> 0 | T21: =IFERROR(B21+E21+H21+K21+N21+Q21, "NA") -> 0 | U21: =(T21/$V$1)/7 -> 0
A22: 4210 - Retail Sales | B22: 50476.5 | C22: =IFERROR(B22/B327, "NA") -> 0.022773739 | E22: 37420.46 | F22: =IFERROR(E22/E327, "NA") -> 0.021268524 | H22: 51519.72 | I22: =IFERROR(H22/H327, "NA") -> 0.021051828 | K22: 20531.92 | L22: =IFERROR(K22/K327, "NA") -> 0.013553807 | N22: 44399.59 | O22: =IFERROR(N22/N327, "NA") -> 0.021002453 | Q22: 9221.53 | R22: =IFERROR(Q22/Q327, "NA") -> 0.0066474304 | T22: =IFERROR(B22+E22+H22+K22+N22+Q22, "NA") -> 213569.72 | U22: =(T22/$V$1)/7 -> 1173.46
A23: 4211 - No show / Min not met | B23: 0 | C23: =IFERROR(B23/B327, "NA") -> 0 | E23: 0 | F23: =IFERROR(E23/E327, "NA") -> 0 | H23: 0 | I23: =IFERROR(H23/H327, "NA") -> 0 | K23: -216 | L23: =IFERROR(K23/K327, "NA") -> -0.00014258882 | N23: 0 | O23: =IFERROR(N23/N327, "NA") -> 0 | Q23: 0 | R23: =IFERROR(Q23/Q327, "NA") -> 0 | T23: =IFERROR(B23+E23+H23+K23+N23+Q23, "NA") -> -216 | U23: =(T23/$V$1)/7 -> -1.1868132
A24: 4215 - Yacht sales | B24: 0 | C24: =IFERROR(B24/B327, "NA") -> 0 | E24: 0 | F24: =IFERROR(E24/E327, "NA") -> 0 | H24: 0 | I24: =IFERROR(H24/H327, "NA") -> 0 | K24: 0 | L24: =IFERROR(K24/K327, "NA") -> 0 | N24: 0 | O24: =IFERROR(N24/N327, "NA") -> 0 | Q24: 0 | R24: =IFERROR(Q24/Q327, "NA") -> 0 | T24: =IFERROR(B24+E24+H24+K24+N24+Q24, "NA") -> 0 | U24: =(T24/$V$1)/7 -> 0
A25: 4216 - Docking fees Revenue | B25: 0 | C25: =IFERROR(B25/B327, "NA") -> 0 | E25: 0 | F25: =IFERROR(E25/E327, "NA") -> 0 | H25: 0 | I25: =IFERROR(H25/H327, "NA") -> 0 | K25: 0 | L25: =IFERROR(K25/K327, "NA") -> 0 | N25: 0 | O25: =IFERROR(N25/N327, "NA") -> 0 | Q25: 0 | R25: =IFERROR(Q25/Q327, "NA") -> 0 | T25: =IFERROR(B25+E25+H25+K25+N25+Q25, "NA") -> 0 | U25: =(T25/$V$1)/7 -> 0
A26: 4220 - Membership Revenue | B26: 95724.78 | C26: =IFERROR(B26/B327, "NA") -> 0.043188635 | E26: 102708.41 | F26: =IFERROR(E26/E327, "NA") -> 0.058375988 | H26: 99171.36 | I26: =IFERROR(H26/H327, "NA") -> 0.040523094 | K26: 89854.81 | L26: =IFERROR(K26/K327, "NA") -> 0.059316165 | N26: 109882.7 | O26: =IFERROR(N26/N327, "NA") -> 0.051978099 | Q26: 75533.59 | R26: =IFERROR(Q26/Q327, "NA") -> 0.05444913 | T26: =IFERROR(B26+E26+H26+K26+N26+Q26, "NA") -> 572875.65 | U26: =(T26/$V$1)/7 -> 3147.6684
A27: 4221 - Application Fee Revenue | B27: 0 | C27: =IFERROR(B27/B327, "NA") -> 0 | E27: 0 | F27: =IFERROR(E27/E327, "NA") -> 0 | H27: 0 | I27: =IFERROR(H27/H327, "NA") -> 0 | K27: 0 | L27: =IFERROR(K27/K327, "NA") -> 0 | N27: 0 | O27: =IFERROR(N27/N327, "NA") -> 0 | Q27: 0 | R27: =IFERROR(Q27/Q327, "NA") -> 0 | T27: =IFERROR(B27+E27+H27+K27+N27+Q27, "NA") -> 0 | U27: =(T27/$V$1)/7 -> 0
A28: 4230 - Retained Service Charge | B28: 0 | C28: =IFERROR(B28/B327, "NA") -> 0 | E28: 0 | F28: =IFERROR(E28/E327, "NA") -> 0 | H28: 0 | I28: =IFERROR(H28/H327, "NA") -> 0 | K28: 0 | L28: =IFERROR(K28/K327, "NA") -> 0 | N28: 0 | O28: =IFERROR(N28/N327, "NA") -> 0 | Q28: 0 | R28: =IFERROR(Q28/Q327, "NA") -> 0 | T28: =IFERROR(B28+E28+H28+K28+N28+Q28, "NA") -> 0 | U28: =(T28/$V$1)/7 -> 0
A29: 4250 - Service Sales | B29: 0 | C29: =IFERROR(B29/B327, "NA") -> 0 | E29: 0 | F29: =IFERROR(E29/E327, "NA") -> 0 | H29: 0 | I29: =IFERROR(H29/H327, "NA") -> 0 | K29: 0 | L29: =IFERROR(K29/K327, "NA") -> 0 | N29: 0 | O29: =IFERROR(N29/N327, "NA") -> 0 | Q29: 0 | R29: =IFERROR(Q29/Q327, "NA") -> 0 | T29: =IFERROR(B29+E29+H29+K29+N29+Q29, "NA") -> 0 | U29: =(T29/$V$1)/7 -> 0
A30: Total Other Sales | B30: =IFERROR(B21+B22+B23+B24+B25+B26+B27+B28+B29, "NA") -> 146201.28 | C30: =IFERROR(B30/B327, "NA") -> 0.065962374 | E30: =IFERROR(E21+E22+E23+E24+E25+E26+E27+E28+E29, "NA") -> 140128.87 | F30: =IFERROR(E30/E327, "NA") -> 0.079644512 | H30: =IFERROR(H21+H22+H23+H24+H25+H26+H27+H28+H29, "NA") -> 150691.08 | I30: =IFERROR(H30/H327, "NA") -> 0.061574922 | K30: =IFERROR(K21+K22+K23+K24+K25+K26+K27+K28+K29, "NA") -> 110170.73 | L30: =IFERROR(K30/K327, "NA") -> 0.072727383 | N30: =IFERROR(N21+N22+N23+N24+N25+N26+N27+N28+N29, "NA") -> 154282.29 | O30: =IFERROR(N30/N327, "NA") -> 0.072980553 | Q30: =IFERROR(Q21+Q22+Q23+Q24+Q25+Q26+Q27+Q28+Q29, "NA") -> 84755.12 | R30: =IFERROR(Q30/Q327, "NA") -> 0.06109656 | T30: =IFERROR(B30+E30+H30+K30+N30+Q30, "NA") -> 786229.37 | U30: =(T30/$V$1)/7 -> 4319.9416
A31: Hotel Sales | T31: =IFERROR(B31+E31+H31+K31+N31+Q31, "NA") -> 0 | U31: =(T31/$V$1)/7 -> 0
A32: 4399 - Hotel Sales | B32: 0 | C32: =IFERROR(B32/B327, "NA") -> 0 | E32: 0 | F32: =IFERROR(E32/E327, "NA") -> 0 | H32: 0 | I32: =IFERROR(H32/H327, "NA") -> 0 | K32: 0 | L32: =IFERROR(K32/K327, "NA") -> 0 | N32: 0 | O32: =IFERROR(N32/N327, "NA") -> 0 | Q32: 0 | R32: =IFERROR(Q32/Q327, "NA") -> 0 | T32: =IFERROR(B32+E32+H32+K32+N32+Q32, "NA") -> 0 | U32: =(T32/$V$1)/7 -> 0
A33: 4301 - Accommodation | B33: 0 | C33: =IFERROR(B33/B327, "NA") -> 0 | E33: 0 | F33: =IFERROR(E33/E327, "NA") -> 0 | H33: 0 | I33: =IFERROR(H33/H327, "NA") -> 0 | K33: 0 | L33: =IFERROR(K33/K327, "NA") -> 0 | N33: 0 | O33: =IFERROR(N33/N327, "NA") -> 0 | Q33: 0 | R33: =IFERROR(Q33/Q327, "NA") -> 0 | T33: =IFERROR(B33+E33+H33+K33+N33+Q33, "NA") -> 0 | U33: =(T33/$V$1)/7 -> 0
A34: 4310 - Mini Bar | B34: 0 | C34: =IFERROR(B34/B327, "NA") -> 0 | E34: 0 | F34: =IFERROR(E34/E327, "NA") -> 0 | H34: 0 | I34: =IFERROR(H34/H327, "NA") -> 0 | K34: 0 | L34: =IFERROR(K34/K327, "NA") -> 0 | N34: 0 | O34: =IFERROR(N34/N327, "NA") -> 0 | Q34: 0 | R34: =IFERROR(Q34/Q327, "NA") -> 0 | T34: =IFERROR(B34+E34+H34+K34+N34+Q34, "NA") -> 0 | U34: =(T34/$V$1)/7 -> 0
A35: 4320 - Destination Fee | B35: 0 | C35: =IFERROR(B35/B327, "NA") -> 0 | E35: 0 | F35: =IFERROR(E35/E327, "NA") -> 0 | H35: 0 | I35: =IFERROR(H35/H327, "NA") -> 0 | K35: 0 | L35: =IFERROR(K35/K327, "NA") -> 0 | N35: 0 | O35: =IFERROR(N35/N327, "NA") -> 0 | Q35: 0 | R35: =IFERROR(Q35/Q327, "NA") -> 0 | T35: =IFERROR(B35+E35+H35+K35+N35+Q35, "NA") -> 0 | U35: =(T35/$V$1)/7 -> 0
A36: 4340 - Other Accommodation | B36: 0 | C36: =IFERROR(B36/B327, "NA") -> 0 | E36: 0 | F36: =IFERROR(E36/E327, "NA") -> 0 | H36: 0 | I36: =IFERROR(H36/H327, "NA") -> 0 | K36: 0 | L36: =IFERROR(K36/K327, "NA") -> 0 | N36: 0 | O36: =IFERROR(N36/N327, "NA") -> 0 | Q36: 0 | R36: =IFERROR(Q36/Q327, "NA") -> 0 | T36: =IFERROR(B36+E36+H36+K36+N36+Q36, "NA") -> 0 | U36: =(T36/$V$1)/7 -> 0
A37: Total Hotel Sales | B37: =IFERROR(B32+B33+B34+B35+B36, "NA") -> 0 | C37: =IFERROR(B37/B327, "NA") -> 0 | E37: =IFERROR(E32+E33+E34+E35+E36, "NA") -> 0 | F37: =IFERROR(E37/E327, "NA") -> 0 | H37: =IFERROR(H32+H33+H34+H35+H36, "NA") -> 0 | I37: =IFERROR(H37/H327, "NA") -> 0 | K37: =IFERROR(K32+K33+K34+K35+K36, "NA") -> 0 | L37: =IFERROR(K37/K327, "NA") -> 0 | N37: =IFERROR(N32+N33+N34+N35+N36, "NA") -> 0 | O37: =IFERROR(N37/N327, "NA") -> 0 | Q37: =IFERROR(Q32+Q33+Q34+Q35+Q36, "NA") -> 0 | R37: =IFERROR(Q37/Q327, "NA") -> 0 | T37: =IFERROR(B37+E37+H37+K37+N37+Q37, "NA") -> 0 | U37: =(T37/$V$1)/7 -> 0
A38: Comps & Promotions | T38: =IFERROR(B38+E38+H38+K38+N38+Q38, "NA") -> 0 | U38: =(T38/$V$1)/7 -> 0
A39: 4900 - Comps & Promotions | B39: 0 | C39: =IFERROR(B39/B327, "NA") -> 0 | E39: 0 | F39: =IFERROR(E39/E327, "NA") -> 0 | H39: 0 | I39: =IFERROR(H39/H327, "NA") -> 0 | K39: 0 | L39: =IFERROR(K39/K327, "NA") -> 0 | N39: 0 | O39: =IFERROR(N39/N327, "NA") -> 0 | Q39: 0 | R39: =IFERROR(Q39/Q327, "NA") -> 0 | T39: =IFERROR(B39+E39+H39+K39+N39+Q39, "NA") -> 0 | U39: =(T39/$V$1)/7 -> 0
A40: 4910 - Employee Discount | B40: -100.25 | C40: =IFERROR(B40/B327, "NA") -> -4.5230302e-05 | E40: 0 | F40: =IFERROR(E40/E327, "NA") -> 0 | H40: 0 | I40: =IFERROR(H40/H327, "NA") -> 0 | K40: 0 | L40: =IFERROR(K40/K327, "NA") -> 0 | N40: 0 | O40: =IFERROR(N40/N327, "NA") -> 0 | Q40: -221.25 | R40: =IFERROR(Q40/Q327, "NA") -> -0.00015949023 | T40: =IFERROR(B40+E40+H40+K40+N40+Q40, "NA") -> -321.5 | U40: =(T40/$V$1)/7 -> -1.7664835
A41: 4915 - Manager Meal | B41: -2319 | C41: =IFERROR(B41/B327, "NA") -> -0.001046275 | E41: -2352 | F41: =IFERROR(E41/E327, "NA") -> -0.0013367973 | H41: -3429.8 | I41: =IFERROR(H41/H327, "NA") -> -0.0014014742 | K41: -1147 | L41: =IFERROR(K41/K327, "NA") -> -0.00075717306 | N41: -1310 | O41: =IFERROR(N41/N327, "NA") -> -0.0006196727 | Q41: -1565 | R41: =IFERROR(Q41/Q327, "NA") -> -0.0011281456 | T41: =IFERROR(B41+E41+H41+K41+N41+Q41, "NA") -> -12122.8 | U41: =(T41/$V$1)/7 -> -66.608791
A42: 4920 - Positive Comp | B42: -3672 | C42: =IFERROR(B42/B327, "NA") -> -0.0016567149 | E42: -4399 | F42: =IFERROR(E42/E327, "NA") -> -0.0025002429 | H42: -10877 | I42: =IFERROR(H42/H327, "NA") -> -0.004444526 | K42: -8407 | L42: =IFERROR(K42/K327, "NA") -> -0.0055497418 | N42: -3132 | O42: =IFERROR(N42/N327, "NA") -> -0.0014815381 | Q42: -2673.6 | R42: =IFERROR(Q42/Q327, "NA") -> -0.0019272908 | T42: =IFERROR(B42+E42+H42+K42+N42+Q42, "NA") -> -33160.6 | U42: =(T42/$V$1)/7 -> -182.2011
A43: 4924 - Marketing/Promotions | B43: -10163 | C43: =IFERROR(B43/B327, "NA") -> -0.0045852923 | E43: -20965 | F43: =IFERROR(E43/E327, "NA") -> -0.011915797 | H43: -33183 | I43: =IFERROR(H43/H327, "NA") -> -0.013559135 | K43: -23229 | L43: =IFERROR(K43/K327, "NA") -> -0.01533424 | N43: -17162 | O43: =IFERROR(N43/N327, "NA") -> -0.0081181855 | Q43: -24608 | R43: =IFERROR(Q43/Q327, "NA") -> -0.017738918 | T43: =IFERROR(B43+E43+H43+K43+N43+Q43, "NA") -> -129310 | U43: =(T43/$V$1)/7 -> -710.49451
...
